Workbook

Sheet Recap
B1: Nama | C1: Status | D1: Gaji Pokok | E1: Uang Transport | F1: Uang Makan | G1: Uang Makan Baru | H1: Lembur | I1: Gaji Per Jam | J1: Bonus | K1: Gaji Harian | L1: Pengembalian Deposit | M1: Total Penghasilan | N1: Working Day | O1: Pay per day | P1: Terlambat (HOURS) | Q1: Keterlambatan | R1: Pengurangan Dari Kejadian | S1: Pengurangan SP | T1: Kasbon | U1: Pembayaran Deposit | V1: Total Pengurang | W1: Service Charge | X1: Take Home Pay | Y1: Take Home Pay Rounding | Z1: 46244 | AA1: 46259 | AB1: 46260 | AC1: Transfer Dari
A2: 1 | B2: Renaldi | C2: Joglo | D2: =SUMIF(Hitungan!$C$2:$C$10,D$1,Hitungan!$G$2:$G$10) -> 1260000 | E2: =SUMIF(Hitungan!$C$2:$C$10,E$1,Hitungan!$G$2:$G$10) -> 1625000 | F2: =SUMIF(Hitungan!$C$2:$C$10,F$1,Hitungan!$G$2:$G$10) -> 1495000 | G2: =SUMIF(Hitungan!$C$2:$C$10,G$1,Hitungan!$G$2:$G$10) -> 0 | H2: =SUMIF(Hitungan!$C$2:$C$10,H$1,Hitungan!$G$2:$G$10) -> 19166.667 | I2: =SUMIF(Hitungan!$C$2:$C$10,I$1,Hitungan!$G$2:$G$10) -> 0 | J2: =SUMIF(Hitungan!$C$2:$C$10,J$1,Hitungan!$G$2:$G$10) -> 0 | K2: =SUMIF(Hitungan!$C$2:$C$10,K$1,Hitungan!$G$2:$G$10) -> 0 | M2: =SUM(D2:L2) -> 4399166.7 | N2: =SUMIF(Hitungan!$C$2:$C$10,"Uang Makan",Hitungan!$F$2:$F$10) -> 26 | O2: =IFERROR(M2/N2,"") -> 169198.72 | P2: =SUMIF(Hitungan!$C$2:$C$10,"Keterlambatan",Hitungan!$F$2:$F$10) -> 2 | Q2: =SUMIF(Hitungan!$C$2:$C$10,"Keterlambatan",Hitungan!$G$2:$G$10) -> 38333.333 | R2: =SUMIF(Hitungan!$C$2:$C$10,"Pengurangan Dari Kejadian",Hitungan!$G$2:$G$10) -> 15000 | S2: =SUMIF(Hitungan!$C$2:$C$10,"Pemotongan SP",Hitungan!$G$2:$G$10) -> 0 | T2: =SUMIF(Hitungan!$C$2:$C$10,"Kasbon",Hitungan!$G$2:$G$10) -> 0 | V2: =SUM(Q2:U2) -> 53333.333 | W2: =SUMIF(Hitungan!$C$2:$C$10,"Service Charge",Hitungan!$G$2:$G$10) -> 0 | X2: =M2-V2+W2 -> 4345833.3 | Y2: =ROUNDDOWN(X2,0) -> 4345833 | Z2: =D2 -> 1260000 | AA2: =Y2-Z2 -> 3085833 | AB2: - | AC2: SGB | AE2: SGB | AF2: =SUMIFS($AA:$AA,$AC:$AC,AE2) -> 27814584
A3: 2 | B3: Ano | C3: Joglo | D3: =SUMIF(Hitungan!$C$44:$C$52,D$1,Hitungan!$G$44:$G$52) -> 1250000 | E3: =SUMIF(Hitungan!$C$44:$C$52,E$1,Hitungan!$G$44:$G$52) -> 765000 | F3: =SUMIF(Hitungan!$C$44:$C$52,F$1,Hitungan!$G$44:$G$52) -> 990000 | G3: =SUMIF(Hitungan!$C$44:$C$52,G$1,Hitungan!$G$44:$G$52) -> 0 | H3: =SUMIF(Hitungan!$C$44:$C$52,H$1,Hitungan!$G$44:$G$52) -> 0 | I3: =SUMIF(Hitungan!$C$44:$C$52,I$1,Hitungan!$G$44:$G$52) -> 0 | J3: =SUMIF(Hitungan!$C$44:$C$52,J$1,Hitungan!$G$44:$G$52) -> 0 | K3: =SUMIF(Hitungan!$C$44:$C$52,K$1,Hitungan!$G$44:$G$52) -> 0 | M3: =SUM(D3:L3) -> 3005000 | N3: =SUMIF(Hitungan!$C$44:$C$52,"Uang Makan",Hitungan!$F$44:$F$52) -> 18 | O3: =IFERROR(M3/N3,"") -> 166944.44 | P3: =SUMIF(Hitungan!$C$44:$C$52,"Keterlambatan",Hitungan!$F$44:$F$52) -> 1 | Q3: =SUMIF(Hitungan!$C$44:$C$52,"Keterlambatan",Hitungan!$G$44:$G$52) -> 18333.333 | R3: =SUMIF(Hitungan!$C$44:$C$52,"Pengurangan Dari Kejadian",Hitungan!$G$44:$G$52) -> 15000 | S3: =SUMIF(Hitungan!$C$44:$C$52,"Pemotongan SP",Hitungan!$G$44:$G$52) -> 0 | T3: =SUMIF(Hitungan!$C$44:$C$52,"Kasbon",Hitungan!$G$44:$G$52) -> 0 | U3: 250000 | V3: =SUM(Q3:U3) -> 283333.33 | W3: =SUMIF(Hitungan!$C$44:$C$52,"Service Charge",Hitungan!$G$44:$G$52) -> 0 | X3: =M3-V3+W3 -> 2721666.7 | Y3: =ROUNDDOWN(X3,0) -> 2721666 | Z3: =D3-V3 -> 966666.67 | AA3: =Y3-Z3 -> 1754999.3 | AB3: - | AC3: SGB | AE3: SBR | AF3: =SUMIFS($AA:$AA,$AC:$AC,AE3) -> 5625803
A4: 3 | B4: Raihan | C4: Joglo | D4: =SUMIF(Hitungan!$C$86:$C$96,D$1,Hitungan!$G$86:$G$96) -> 1250000 | E4: =SUMIF(Hitungan!$C$86:$C$96,E$1,Hitungan!$G$86:$G$96) -> 990000 | F4: =SUMIF(Hitungan!$C$86:$C$96,F$1,Hitungan!$G$86:$G$96) -> 1265000 | G4: =SUMIF(Hitungan!$C$86:$C$96,G$1,Hitungan!$G$86:$G$96) -> 0 | H4: =SUMIF(Hitungan!$C$86:$C$96,H$1,Hitungan!$G$86:$G$96) -> 0 | I4: =SUMIF(Hitungan!$C$86:$C$96,I$1,Hitungan!$G$86:$G$96) -> 0 | J4: =SUMIF(Hitungan!$C$86:$C$96,J$1,Hitungan!$G$86:$G$96) -> 0 | K4: =SUMIF(Hitungan!$C$86:$C$96,K$1,Hitungan!$G$86:$G$96) -> 0 | M4: =SUM(D4:L4) -> 3505000 | N4: =SUMIF(Hitungan!$C$86:$C$96,"Uang Makan",Hitungan!$F$86:$F$96) -> 23 | O4: =IFERROR(M4/N4,"") -> 152391.3 | P4: =SUMIF(Hitungan!$C$86:$C$96,"Keterlambatan",Hitungan!$F$86:$F$96) -> 2 | Q4: =SUMIF(Hitungan!$C$86:$C$96,"Keterlambatan",Hitungan!$G$86:$G$96) -> 36666.667 | R4: =SUMIF(Hitungan!$C$86:$C$96,"Pengurangan Dari Kejadian",Hitungan!$G$86:$G$96) -> 15000 | S4: =SUMIF(Hitungan!$C$86:$C$96,"Pemotongan SP",Hitungan!$G$86:$G$96) -> 0 | T4: =SUMIF(Hitungan!$C$86:$C$96,"Kasbon",Hitungan!$G$86:$G$96) -> 0 | U4: 250000 | V4: =SUM(Q4:U4) -> 301666.67 | W4: =SUMIF(Hitungan!$C$86:$C$96,"Service Charge",Hitungan!$G$86:$G$96) -> 0 | X4: =M4-V4+W4 -> 3203333.3 | Y4: =ROUNDDOWN(X4,0) -> 3203333 | Z4: =D4-V4 -> 948333.33 | AA4: =Y4-Z4 -> 2254999.7 | AB4: - | AC4: SGB | AE4: SBB | AF4: =SUMIFS($AA:$AA,$AC:$AC,AE4) -> 16312768
A5: 4 | B5: Teguh | C5: Joglo | D5: =SUMIF(Hitungan!$C$130:$C$138,D$1,Hitungan!$G$130:$G$138) -> 388221.15 | E5: =SUMIF(Hitungan!$C$130:$C$138,E$1,Hitungan!$G$130:$G$138) -> 363375 | F5: =SUMIF(Hitungan!$C$130:$C$138,F$1,Hitungan!$G$130:$G$138) -> 444125 | G5: =SUMIF(Hitungan!$C$130:$C$138,G$1,Hitungan!$G$130:$G$138) -> 0 | H5: =SUMIF(Hitungan!$C$130:$C$138,H$1,Hitungan!$G$130:$G$138) -> 0 | I5: =SUMIF(Hitungan!$C$130:$C$138,I$1,Hitungan!$G$130:$G$138) -> 0 | J5: =SUMIF(Hitungan!$C$130:$C$138,J$1,Hitungan!$G$130:$G$138) -> 0 | K5: =SUMIF(Hitungan!$C$130:$C$138,K$1,Hitungan!$G$130:$G$138) -> 0 | M5: =SUM(D5:L5) -> 1195721.2 | N5: =SUMIF(Hitungan!$C$130:$C$138,"Uang Makan",Hitungan!$F$130:$F$138) -> 9.5 | O5: =IFERROR(M5/N5,"") -> 125865.38 | P5: =SUMIF(Hitungan!$C$130:$C$138,"Keterlambatan",Hitungan!$F$130:$F$138) -> 0 | Q5: =SUMIF(Hitungan!$C$130:$C$138,"Keterlambatan",Hitungan!$G$130:$G$138) -> 0 | R5: =SUMIF(Hitungan!$C$130:$C$138,"Pengurangan Dari Kejadian",Hitungan!$G$130:$G$138) -> 15000 | S5: =SUMIF(Hitungan!$C$130:$C$138,"Pemotongan SP",Hitungan!$G$130:$G$138) -> 0 | T5: =SUMIF(Hitungan!$C$130:$C$138,"Kasbon",Hitungan!$G$130:$G$138) -> 0 | V5: =SUM(Q5:U5) -> 15000 | W5: =SUMIF(Hitungan!$C$130:$C$138,"Service Charge",Hitungan!$G$130:$G$138) -> 0 | X5: =M5-V5+W5 -> 1180721.2 | Y5: =ROUNDDOWN(X5,0) -> 1180721 | Z5: =Y5 -> 1180721 | AA5: =Y5-Z5 -> 0 | AB5: - | AC5: SGB
A6: 5 | B6: Titus | C6: GS | D6: =SUMIF(Hitungan!$C$337:$C$345,D$1,Hitungan!$G$337:$G$345) -> 3190000 | E6: =SUMIF(Hitungan!$C$337:$C$345,E$1,Hitungan!$G$337:$G$345) -> 546000 | F6: =SUMIF(Hitungan!$C$337:$C$345,F$1,Hitungan!$G$337:$G$345) -> 1404000 | G6: =SUMIF(Hitungan!$C$337:$C$345,G$1,Hitungan!$G$337:$G$345) -> 0 | H6: =SUMIF(Hitungan!$C$337:$C$345,H$1,Hitungan!$G$337:$G$345) -> 0 | I6: =SUMIF(Hitungan!$C$337:$C$345,I$1,Hitungan!$G$337:$G$345) -> 0 | J6: =SUMIF(Hitungan!$C$337:$C$345,J$1,Hitungan!$G$337:$G$345) -> 0 | K6: =SUMIF(Hitungan!$C$337:$C$345,K$1,Hitungan!$G$337:$G$345) -> 0 | M6: =SUM(D6:L6) -> 5140000 | N6: =SUMIF(Hitungan!$C$337:$C$345,"Uang Makan",Hitungan!$F$337:$F$345) -> 26 | O6: =IFERROR(M6/N6,"") -> 197692.31 | P6: =SUMIF(Hitungan!$C$337:$C$345,"Keterlambatan",Hitungan!$F$337:$F$345) -> 0 | Q6: =SUMIF(Hitungan!$C$337:$C$345,"Keterlambatan",Hitungan!$G$337:$G$345) -> 0 | R6: =SUMIF(Hitungan!$C$337:$C$345,"Pengurangan Dari Kejadian",Hitungan!$G$337:$G$345) -> 318000 | S6: =SUMIF(Hitungan!$C$337:$C$345,"Pemotongan SP",Hitungan!$G$337:$G$345) -> 0 | T6: =SUMIF(Hitungan!$C$337:$C$345,"Kasbon",Hitungan!$G$337:$G$345) -> 0 | V6: =SUM(Q6:U6) -> 318000 | W6: =SUMIF(Hitungan!$C$337:$C$345,"Service Charge",Hitungan!$G$337:$G$345) -> 750587 | X6: =M6-V6+W6 -> 5572587 | Y6: =ROUNDDOWN(X6,0) -> 5572587 | Z6: =D6 -> 3190000 | AA6: =Y6-Z6 -> 2382587 | AB6: - | AC6: SGB
A7: 6 | B7: Sekar | C7: GS | D7: =SUMIF(Hitungan!$C$172:$C$181,D$1,Hitungan!$G$172:$G$181) -> 3220000 | E7: =SUMIF(Hitungan!$C$172:$C$181,E$1,Hitungan!$G$172:$G$181) -> 546000 | F7: =SUMIF(Hitungan!$C$172:$C$181,F$1,Hitungan!$G$172:$G$181) -> 1352000 | G7: =SUMIF(Hitungan!$C$172:$C$181,G$1,Hitungan!$G$172:$G$181) -> 0 | H7: =SUMIF(Hitungan!$C$172:$C$181,H$1,Hitungan!$G$172:$G$181) -> 0 | I7: =SUMIF(Hitungan!$C$172:$C$181,I$1,Hitungan!$G$172:$G$181) -> 0 | J7: =SUMIF(Hitungan!$C$172:$C$181,J$1,Hitungan!$G$172:$G$181) -> 0 | K7: =SUMIF(Hitungan!$C$172:$C$181,K$1,Hitungan!$G$172:$G$181) -> 0 | M7: =SUM(D7:L7) -> 5118000 | N7: =SUMIF(Hitungan!$C$172:$C$181,"Uang Makan",Hitungan!$F$172:$F$181) -> 26 | O7: =IFERROR(M7/N7,"") -> 196846.15 | P7: =SUMIF(Hitungan!$C$172:$C$181,"Keterlambatan",Hitungan!$F$172:$F$181) -> 2 | Q7: =SUMIF(Hitungan!$C$172:$C$181,"Keterlambatan",Hitungan!$G$172:$G$181) -> 34666.667 | R7: =SUMIF(Hitungan!$C$172:$C$181,"Pengurangan Dari Kejadian",Hitungan!$G$172:$G$181) -> 65000 | S7: =SUMIF(Hitungan!$C$172:$C$181,"Pemotongan SP",Hitungan!$G$172:$G$181) -> 0 | T7: =SUMIF(Hitungan!$C$172:$C$181,"Kasbon",Hitungan!$G$172:$G$181) -> 0 | V7: =SUM(Q7:U7) -> 99666.667 | W7: =SUMIF(Hitungan!$C$172:$C$181,"Service Charge",Hitungan!$G$172:$G$181) -> 718861 | X7: =M7-V7+W7 -> 5737194.3 | Y7: =ROUNDDOWN(X7,0) -> 5737194 | Z7: =D7 -> 3220000 | AA7: =Y7-Z7 -> 2517194 | AB7: - | AC7: SGB
A8: 7 | B8: Ahmad | C8: GS | D8: =SUMIF(Hitungan!$C$214:$C$222,D$1,Hitungan!$G$214:$G$222) -> 2250000 | E8: =SUMIF(Hitungan!$C$214:$C$222,E$1,Hitungan!$G$214:$G$222) -> 504000 | F8: =SUMIF(Hitungan!$C$214:$C$222,F$1,Hitungan!$G$214:$G$222) -> 1080000 | G8: =SUMIF(Hitungan!$C$214:$C$222,G$1,Hitungan!$G$214:$G$222) -> 0 | H8: =SUMIF(Hitungan!$C$214:$C$222,H$1,Hitungan!$G$214:$G$222) -> 0 | I8: =SUMIF(Hitungan!$C$214:$C$222,I$1,Hitungan!$G$214:$G$222) -> 0 | J8: =SUMIF(Hitungan!$C$214:$C$222,J$1,Hitungan!$G$214:$G$222) -> 0 | K8: =SUMIF(Hitungan!$C$214:$C$222,K$1,Hitungan!$G$214:$G$222) -> 0 | M8: =SUM(D8:L8) -> 3834000 | N8: =SUMIF(Hitungan!$C$214:$C$222,"Uang Makan",Hitungan!$F$214:$F$222) -> 24 | O8: =IFERROR(M8/N8,"") -> 159750 | P8: =SUMIF(Hitungan!$C$214:$C$222,"Keterlambatan",Hitungan!$F$214:$F$222) -> 0 | Q8: =SUMIF(Hitungan!$C$214:$C$222,"Keterlambatan",Hitungan!$G$214:$G$222) -> 0 | R8: =SUMIF(Hitungan!$C$214:$C$222,"Pengurangan Dari Kejadian",Hitungan!$G$214:$G$222) -> 72500 | S8: =SUMIF(Hitungan!$C$214:$C$222,"Pemotongan SP",Hitungan!$G$214:$G$222) -> 0 | T8: =SUMIF(Hitungan!$C$214:$C$222,"Kasbon",Hitungan!$G$214:$G$222) -> 0 | V8: =SUM(Q8:U8) -> 72500 | W8: =SUMIF(Hitungan!$C$214:$C$222,"Service Charge",Hitungan!$G$214:$G$222) -> 707240 | X8: =M8-V8+W8 -> 4468740 | Y8: =ROUNDDOWN(X8,0) -> 4468740 | Z8: =D8 -> 2250000 | AA8: =Y8-Z8 -> 2218740 | AB8: - | AC8: SGB
A9: 8 | B9: Valen | C9: GS | D9: =SUMIF(Hitungan!$C$378:$C$386,D$1,Hitungan!$G$378:$G$386) -> 2250000 | E9: =SUMIF(Hitungan!$C$378:$C$386,E$1,Hitungan!$G$378:$G$386) -> 504000 | F9: =SUMIF(Hitungan!$C$378:$C$386,F$1,Hitungan!$G$378:$G$386) -> 960000 | G9: =SUMIF(Hitungan!$C$378:$C$386,G$1,Hitungan!$G$378:$G$386) -> 0 | H9: =SUMIF(Hitungan!$C$378:$C$386,H$1,Hitungan!$G$378:$G$386) -> 0 | I9: =SUMIF(Hitungan!$C$378:$C$386,I$1,Hitungan!$G$378:$G$386) -> 0 | J9: =SUMIF(Hitungan!$C$378:$C$386,J$1,Hitungan!$G$378:$G$386) -> 0 | K9: =SUMIF(Hitungan!$C$378:$C$386,K$1,Hitungan!$G$378:$G$386) -> 0 | M9: =SUM(D9:L9) -> 3714000 | N9: =SUMIF(Hitungan!$C$378:$C$386,"Uang Makan",Hitungan!$F$378:$F$386) -> 24 | O9: =IFERROR(M9/N9,"") -> 154750 | P9: =SUMIF(Hitungan!$C$378:$C$386,"Keterlambatan",Hitungan!$F$378:$F$386) -> 3 | Q9: =SUMIF(Hitungan!$C$378:$C$386,"Keterlambatan",Hitungan!$G$378:$G$386) -> 40000 | R9: =SUMIF(Hitungan!$C$378:$C$386,"Pengurangan Dari Kejadian",Hitungan!$G$378:$G$386) -> 100000 | S9: =SUMIF(Hitungan!$C$378:$C$386,"Pemotongan SP",Hitungan!$G$378:$G$386) -> 0 | T9: =SUMIF(Hitungan!$C$378:$C$386,"Kasbon",Hitungan!$G$378:$G$386) -> 0 | V9: =SUM(Q9:U9) -> 140000 | W9: =SUMIF(Hitungan!$C$378:$C$386,"Service Charge",Hitungan!$G$378:$G$386) -> 664322 | X9: =M9-V9+W9 -> 4238322 | Y9: =ROUNDDOWN(X9,0) -> 4238322 | Z9: =D9 -> 2250000 | AA9: =Y9-Z9 -> 1988322 | AB9: - | AC9: SGB
A10: 9 | B10: Rifai | C10: GS | D10: =SUMIF(Hitungan!$C$419:$C$427,D$1,Hitungan!$G$419:$G$427) -> 1305000 | E10: =SUMIF(Hitungan!$C$419:$C$427,E$1,Hitungan!$G$419:$G$427) -> 378000 | F10: =SUMIF(Hitungan!$C$419:$C$427,F$1,Hitungan!$G$419:$G$427) -> 704700 | G10: =SUMIF(Hitungan!$C$419:$C$427,G$1,Hitungan!$G$419:$G$427) -> 0 | H10: =SUMIF(Hitungan!$C$419:$C$427,H$1,Hitungan!$G$419:$G$427) -> 0 | I10: =SUMIF(Hitungan!$C$419:$C$427,I$1,Hitungan!$G$419:$G$427) -> 0 | J10: =SUMIF(Hitungan!$C$419:$C$427,J$1,Hitungan!$G$419:$G$427) -> 0 | K10: =SUMIF(Hitungan!$C$419:$C$427,K$1,Hitungan!$G$419:$G$427) -> 0 | M10: =SUM(D10:L10) -> 2387700 | N10: =SUMIF(Hitungan!$C$419:$C$427,"Uang Makan",Hitungan!$F$419:$F$427) -> 18 | O10: =IFERROR(M10/N10,"") -> 132650 | P10: =SUMIF(Hitungan!$C$419:$C$427,"Keterlambatan",Hitungan!$F$419:$F$427) -> 0 | Q10: =SUMIF(Hitungan!$C$419:$C$427,"Keterlambatan",Hitungan!$G$419:$G$427) -> 0 | R10: =SUMIF(Hitungan!$C$419:$C$427,"Pengurangan Dari Kejadian",Hitungan!$G$419:$G$427) -> 235000 | S10: =SUMIF(Hitungan!$C$419:$C$427,"Pemotongan SP",Hitungan!$G$419:$G$427) -> 0 | T10: =SUMIF(Hitungan!$C$419:$C$427,"Kasbon",Hitungan!$G$419:$G$427) -> 0 | V10: =SUM(Q10:U10) -> 235000 | W10: =SUMIF(Hitungan!$C$419:$C$427,"Service Charge",Hitungan!$G$419:$G$427) -> 524296 | X10: =M10-V10+W10 -> 2676996 | Y10: =ROUNDDOWN(X10,0) -> 2676996 | AA10: =Y10-Z10 -> 2676996 | AB10: - | AC10: SGB
A11: 10 | B11: Audy | C11: GS | D11: =SUMIF(Hitungan!$C$255:$C$263,D$1,Hitungan!$G$255:$G$263) -> 1740000 | E11: =SUMIF(Hitungan!$C$255:$C$263,E$1,Hitungan!$G$255:$G$263) -> 462000 | F11: =SUMIF(Hitungan!$C$255:$C$263,F$1,Hitungan!$G$255:$G$263) -> 861300 | G11: =SUMIF(Hitungan!$C$255:$C$263,G$1,Hitungan!$G$255:$G$263) -> 0 | H11: =SUMIF(Hitungan!$C$255:$C$263,H$1,Hitungan!$G$255:$G$263) -> 0 | I11: =SUMIF(Hitungan!$C$255:$C$263,I$1,Hitungan!$G$255:$G$263) -> 0 | J11: =SUMIF(Hitungan!$C$255:$C$263,J$1,Hitungan!$G$255:$G$263) -> 0 | K11: =SUMIF(Hitungan!$C$255:$C$263,K$1,Hitungan!$G$255:$G$263) -> 0 | M11: =SUM(D11:L11) -> 3063300 | N11: =SUMIF(Hitungan!$C$255:$C$263,"Uang Makan",Hitungan!$F$255:$F$263) -> 22 | O11: =IFERROR(M11/N11,"") -> 139240.91 | P11: =SUMIF(Hitungan!$C$255:$C$263,"Keterlambatan",Hitungan!$F$255:$F$263) -> 1 | Q11: =SUMIF(Hitungan!$C$255:$C$263,"Keterlambatan",Hitungan!$G$255:$G$263) -> 13050 | R11: =SUMIF(Hitungan!$C$255:$C$263,"Pengurangan Dari Kejadian",Hitungan!$G$255:$G$263) -> 198650 | S11: =SUMIF(Hitungan!$C$255:$C$263,"Pemotongan SP",Hitungan!$G$255:$G$263) -> 0 | T11: =SUMIF(Hitungan!$C$255:$C$263,"Kasbon",Hitungan!$G$255:$G$263) -> 0 | V11: =SUM(Q11:U11) -> 211700 | W11: =SUMIF(Hitungan!$C$255:$C$263,"Service Charge",Hitungan!$G$255:$G$263) -> 408247 | X11: =M11-V11+W11 -> 3259847 | Y11: =ROUNDDOWN(X11,0) -> 3259847 | AA11: =Y11-Z11 -> 3259847 | AB11: - | AC11: SGB
A12: 11 | B12: Wise | C12: GS | D12: =SUMIF(Hitungan!$C$296:$C$304,D$1,Hitungan!$G$296:$G$304) -> 0 | E12: =SUMIF(Hitungan!$C$296:$C$304,E$1,Hitungan!$G$296:$G$304) -> 0 | F12: =SUMIF(Hitungan!$C$296:$C$304,F$1,Hitungan!$G$296:$G$304) -> 0 | G12: =SUMIF(Hitungan!$C$296:$C$304,G$1,Hitungan!$G$296:$G$304) -> 0 | H12: =SUMIF(Hitungan!$C$296:$C$304,H$1,Hitungan!$G$296:$G$304) -> 0 | I12: =SUMIF(Hitungan!$C$296:$C$304,I$1,Hitungan!$G$296:$G$304) -> 0 | J12: =SUMIF(Hitungan!$C$296:$C$304,J$1,Hitungan!$G$296:$G$304) -> 0 | K12: =SUMIF(Hitungan!$C$296:$C$304,K$1,Hitungan!$G$296:$G$304) -> 900000 | M12: =SUM(D12:L12) -> 900000 | N12: =SUMIF(Hitungan!$C$296:$C$304,"Uang Makan",Hitungan!$F$296:$F$304) -> 6 | O12: =IFERROR(M12/N12,"") -> 150000 | P12: =SUMIF(Hitungan!$C$296:$C$304,"Keterlambatan",Hitungan!$F$296:$F$304) -> 0 | Q12: =SUMIF(Hitungan!$C$296:$C$304,"Keterlambatan",Hitungan!$G$296:$G$304) -> 0 | R12: =SUMIF(Hitungan!$C$296:$C$304,"Pengurangan Dari Kejadian",Hitungan!$G$296:$G$304) -> 0 | S12: =SUMIF(Hitungan!$C$296:$C$304,"Pemotongan SP",Hitungan!$G$296:$G$304) -> 0 | T12: =SUMIF(Hitungan!$C$296:$C$304,"Kasbon",Hitungan!$G$296:$G$304) -> 0 | V12: =SUM(Q12:U12) -> 0 | W12: =SUMIF(Hitungan!$C$296:$C$304,"Service Charge",Hitungan!$G$296:$G$304) -> 0 | X12: =M12-V12+W12 -> 900000 | Y12: =ROUNDDOWN(X12,0) -> 900000 | Z12: =D12 -> 0 | AA12: =Y12-Z12 -> 900000 | AB12: - | AC12: SGB
A13: 12 | B13: Nur Andika | C13: GS | D13: =SUMIF(Hitungan!$C$501:$C$509,D$1,Hitungan!$G$501:$G$509) -> 0 | E13: =SUMIF(Hitungan!$C$501:$C$509,E$1,Hitungan!$G$501:$G$509) -> 0 | F13: =SUMIF(Hitungan!$C$501:$C$509,F$1,Hitungan!$G$501:$G$509) -> 0 | G13: =SUMIF(Hitungan!$C$501:$C$509,G$1,Hitungan!$G$501:$G$509) -> 0 | H13: =SUMIF(Hitungan!$C$501:$C$509,H$1,Hitungan!$G$501:$G$509) -> 0 | I13: =SUMIF(Hitungan!$C$501:$C$509,I$1,Hitungan!$G$501:$G$509) -> 0 | J13: =SUMIF(Hitungan!$C$501:$C$509,J$1,Hitungan!$G$501:$G$509) -> 0 | K13: =SUMIF(Hitungan!$C$501:$C$509,K$1,Hitungan!$G$501:$G$509) -> 150000 | M13: =SUM(D13:L13) -> 150000 | N13: =SUMIF(Hitungan!$C$501:$C$509,"Uang Makan",Hitungan!$F$501:$F$509) -> 1 | O13: =IFERROR(M13/N13,"") -> 150000 | P13: =SUMIF(Hitungan!$C$501:$C$509,"Keterlambatan",Hitungan!$F$501:$F$509) -> 0 | Q13: =SUMIF(Hitungan!$C$501:$C$509,"Keterlambatan",Hitungan!$G$501:$G$509) -> 0 | R13: =SUMIF(Hitungan!$C$501:$C$509,"Pengurangan Dari Kejadian",Hitungan!$G$501:$G$509) -> 0 | S13: =SUMIF(Hitungan!$C$501:$C$509,"Pemotongan SP",Hitungan!$G$501:$G$509) -> 0 | T13: =SUMIF(Hitungan!$C$501:$C$509,"Kasbon",Hitungan!$G$501:$G$509) -> 0 | V13: =SUM(Q13:U13) -> 0 | W13: =SUMIF(Hitungan!$C$501:$C$509,"Service Charge",Hitungan!$G$501:$G$509) -> 0 | X13: =M13-V13+W13 -> 150000 | Y13: =ROUNDDOWN(X13,0) -> 150000 | Z13: =D13 -> 0 | AB13: - | AC13: SGB
A14: 13 | B14: Jerrel | C14: GS | D14: =SUMIF(Hitungan!$C$992:$C$1000,D$1,Hitungan!$G$992:$G$1000) -> 0 | E14: =SUMIF(Hitungan!$C$992:$C$1000,E$1,Hitungan!$G$992:$G$1000) -> 0 | F14: =SUMIF(Hitungan!$C$992:$C$1000,F$1,Hitungan!$G$992:$G$1000) -> 0 | G14: =SUMIF(Hitungan!$C$992:$C$1000,G$1,Hitungan!$G$992:$G$1000) -> 0 | H14: =SUMIF(Hitungan!$C$992:$C$1000,H$1,Hitungan!$G$992:$G$1000) -> 0 | I14: =SUMIF(Hitungan!$C$992:$C$1000,I$1,Hitungan!$G$992:$G$1000) -> 0 | J14: =SUMIF(Hitungan!$C$992:$C$1000,J$1,Hitungan!$G$992:$G$1000) -> 0 | K14: =SUMIF(Hitungan!$C$992:$C$1000,K$1,Hitungan!$G$992:$G$1000) -> 1800000 | M14: =SUM(D14:L14) -> 1800000 | N14: =SUMIF(Hitungan!$C$992:$C$1000,"Uang Makan",Hitungan!$F$992:$F$1000) -> 12 | O14: =IFERROR(M14/N14,"") -> 150000 | P14: =SUMIF(Hitungan!$C$992:$C$1000,"Keterlambatan",Hitungan!$F$992:$F$1000) -> 0 | Q14: =SUMIF(Hitungan!$C$992:$C$1000,"Keterlambatan",Hitungan!$G$992:$G$1000) -> 0 | R14: =SUMIF(Hitungan!$C$992:$C$1000,"Pengurangan Dari Kejadian",Hitungan!$G$992:$G$1000) -> 0 | S14: =SUMIF(Hitungan!$C$992:$C$1000,"Pemotongan SP",Hitungan!$G$992:$G$1000) -> 0 | T14: =SUMIF(Hitungan!$C$992:$C$1000,"Kasbon",Hitungan!$G$992:$G$1000) -> 0 | V14: =SUM(Q14:U14) -> 0 | W14: =SUMIF(Hitungan!$C$992:$C$1000,"Service Charge",Hitungan!$G$992:$G$1000) -> 0 | X14: =M14-V14+W14 -> 1800000 | Y14: =ROUNDDOWN(X14,0) -> 1800000 | Z14: =D14 -> 0 | AA14: =Y14-Z14 -> 1800000 | AB14: - | AC14: SGB
A15: 14 | B15: Made | C15: GS | D15: =SUMIF(Hitungan!$C$460:$C$468,D$1,Hitungan!$G$460:$G$468) -> 1377500 | E15: =SUMIF(Hitungan!$C$460:$C$468,E$1,Hitungan!$G$460:$G$468) -> 399000 | F15: =SUMIF(Hitungan!$C$460:$C$468,F$1,Hitungan!$G$460:$G$468) -> 743850 | G15: =SUMIF(Hitungan!$C$460:$C$468,G$1,Hitungan!$G$460:$G$468) -> 0 | H15: =SUMIF(Hitungan!$C$460:$C$468,H$1,Hitungan!$G$460:$G$468) -> 0 | I15: =SUMIF(Hitungan!$C$460:$C$468,I$1,Hitungan!$G$460:$G$468) -> 0 | J15: =SUMIF(Hitungan!$C$460:$C$468,J$1,Hitungan!$G$460:$G$468) -> 0 | K15: =SUMIF(Hitungan!$C$460:$C$468,K$1,Hitungan!$G$460:$G$468) -> 0 | M15: =SUM(D15:L15) -> 2520350 | N15: =SUMIF(Hitungan!$C$460:$C$468,"Uang Makan",Hitungan!$F$460:$F$468) -> 19 | O15: =IFERROR(M15/N15,"") -> 132650 | P15: =SUMIF(Hitungan!$C$460:$C$468,"Keterlambatan",Hitungan!$F$460:$F$468) -> 1 | Q15: =SUMIF(Hitungan!$C$460:$C$468,"Keterlambatan",Hitungan!$G$460:$G$468) -> 13050 | R15: =SUMIF(Hitungan!$C$460:$C$468,"Pengurangan Dari Kejadian",Hitungan!$G$460:$G$468) -> 229000 | S15: =SUMIF(Hitungan!$C$460:$C$468,"Pemotongan SP",Hitungan!$G$460:$G$468) -> 0 | T15: =SUMIF(Hitungan!$C$460:$C$468,"Kasbon",Hitungan!$G$460:$G$468) -> 0 | V15: =SUM(Q15:U15) -> 242050 | W15: =SUMIF(Hitungan!$C$460:$C$468,"Service Charge",Hitungan!$G$460:$G$468) -> 321766 | X15: =M15-V15+W15 -> 2600066 | Y15: =ROUNDDOWN(X15,0) -> 2600066 | AA15: =Y15-Z15 -> 2600066 | AB15: - | AC15: SGB
A16: 15 | B16: Maman | C16: GS | K16: 300000 | M16: 300000 | N16: 3 | AA16: 375000 | AC16: SGB
A17: 15 | B17: Irvan | C17: KG | D17: =SUMIF(Hitungan!$C$787:$C$795,D$1,Hitungan!$G$787:$G$795) -> 3190000 | E17: =SUMIF(Hitungan!$C$787:$C$795,E$1,Hitungan!$G$787:$G$795) -> 546000 | F17: =SUMIF(Hitungan!$C$787:$C$795,F$1,Hitungan!$G$787:$G$795) -> 1404000 | G17: =SUMIF(Hitungan!$C$787:$C$795,G$1,Hitungan!$G$787:$G$795) -> 0 | H17: =SUMIF(Hitungan!$C$787:$C$795,H$1,Hitungan!$G$787:$G$795) -> 18000 | I17: =SUMIF(Hitungan!$C$787:$C$795,I$1,Hitungan!$G$787:$G$795) -> 0 | J17: =SUMIF(Hitungan!$C$787:$C$795,J$1,Hitungan!$G$787:$G$795) -> 0 | K17: =SUMIF(Hitungan!$C$787:$C$795,K$1,Hitungan!$G$787:$G$795) -> 0 | M17: =SUM(D17:L17) -> 5158000 | N17: =SUMIF(Hitungan!$C$787:$C$795,"Uang Makan",Hitungan!$F$787:$F$795) -> 26 | O17: =IFERROR(M17/N17,"") -> 198384.62 | P17: =SUMIF(Hitungan!$C$787:$C$795,"Keterlambatan",Hitungan!$F$787:$F$795) -> 0 | Q17: =SUMIF(Hitungan!$C$787:$C$795,"Keterlambatan",Hitungan!$G$787:$G$795) -> 0 | R17: =SUMIF(Hitungan!$C$787:$C$795,"Pengurangan Dari Kejadian",Hitungan!$G$787:$G$795) -> 0 | S17: =SUMIF(Hitungan!$C$787:$C$795,"Pemotongan SP",Hitungan!$G$787:$G$795) -> 0 | T17: =SUMIF(Hitungan!$C$787:$C$795,"Kasbon",Hitungan!$G$787:$G$795) -> 0 | V17: =SUM(Q17:U17) -> 0 | W17: =SUMIF(Hitungan!$C$787:$C$795,"Service Charge",Hitungan!$G$787:$G$795) -> 401719 | X17: =M17-V17+W17 -> 5559719 | Y17: =ROUNDDOWN(X17,0) -> 5559719 | Z17: =D17 -> 3190000 | AA17: =Y17-Z17 -> 2369719 | AB17: - | AC17: SBB
A18: 16 | B18: Rizky | C18: KG | D18: =SUMIF(Hitungan!$C$828:$C$836,D$1,Hitungan!$G$828:$G$836) -> 1800000 | E18: =SUMIF(Hitungan!$C$828:$C$836,E$1,Hitungan!$G$828:$G$836) -> 315000 | F18: =SUMIF(Hitungan!$C$828:$C$836,F$1,Hitungan!$G$828:$G$836) -> 690000 | G18: =SUMIF(Hitungan!$C$828:$C$836,G$1,Hitungan!$G$828:$G$836) -> 0 | H18: =SUMIF(Hitungan!$C$828:$C$836,H$1,Hitungan!$G$828:$G$836) -> 0 | I18: =SUMIF(Hitungan!$C$828:$C$836,I$1,Hitungan!$G$828:$G$836) -> 0 | J18: =SUMIF(Hitungan!$C$828:$C$836,J$1,Hitungan!$G$828:$G$836) -> 0 | K18: =SUMIF(Hitungan!$C$828:$C$836,K$1,Hitungan!$G$828:$G$836) -> 0 | M18: =SUM(D18:L18) -> 2805000 | N18: =SUMIF(Hitungan!$C$828:$C$836,"Uang Makan",Hitungan!$F$828:$F$836) -> 15 | O18: =IFERROR(M18/N18,"") -> 187000 | P18: =SUMIF(Hitungan!$C$828:$C$836,"Keterlambatan",Hitungan!$F$828:$F$836) -> 2 | Q18: =SUMIF(Hitungan!$C$828:$C$836,"Keterlambatan",Hitungan!$G$828:$G$836) -> 30666.667 | R18: =SUMIF(Hitungan!$C$828:$C$836,"Pengurangan Dari Kejadian",Hitungan!$G$828:$G$836) -> 0 | S18: =SUMIF(Hitungan!$C$828:$C$836,"Pemotongan SP",Hitungan!$G$828:$G$836) -> 0 | T18: =SUMIF(Hitungan!$C$828:$C$836,"Kasbon",Hitungan!$G$828:$G$836) -> 0 | V18: =SUM(Q18:U18) -> 30666.667 | W18: =SUMIF(Hitungan!$C$828:$C$836,"Service Charge",Hitungan!$G$828:$G$836) -> 259727 | X18: =M18-V18+W18 -> 3034060.3 | Y18: =ROUNDDOWN(X18,0) -> 3034060 | Z18: =D18 -> 1800000 | AA18: =Y18-Z18 -> 1234060 | AB18: - | AC18: SBB
A19: 17 | B19: Sabrina | C19: KG | D19: =SUMIF(Hitungan!$C$665:$C$673,D$1,Hitungan!$G$665:$G$673) -> 1800000 | E19: =SUMIF(Hitungan!$C$665:$C$673,E$1,Hitungan!$G$665:$G$673) -> 462000 | F19: =SUMIF(Hitungan!$C$665:$C$673,F$1,Hitungan!$G$665:$G$673) -> 1012000 | G19: =SUMIF(Hitungan!$C$665:$C$673,G$1,Hitungan!$G$665:$G$673) -> 0 | H19: =SUMIF(Hitungan!$C$665:$C$673,H$1,Hitungan!$G$665:$G$673) -> 0 | I19: =SUMIF(Hitungan!$C$665:$C$673,I$1,Hitungan!$G$665:$G$673) -> 0 | J19: =SUMIF(Hitungan!$C$665:$C$673,J$1,Hitungan!$G$665:$G$673) -> 0 | K19: =SUMIF(Hitungan!$C$665:$C$673,K$1,Hitungan!$G$665:$G$673) -> 0 | M19: =SUM(D19:L19) -> 3274000 | N19: =SUMIF(Hitungan!$C$665:$C$673,"Uang Makan",Hitungan!$F$665:$F$673) -> 22 | O19: =IFERROR(M19/N19,"") -> 148818.18 | P19: =SUMIF(Hitungan!$C$665:$C$673,"Keterlambatan",Hitungan!$F$665:$F$673) -> 0 | Q19: =SUMIF(Hitungan!$C$665:$C$673,"Keterlambatan",Hitungan!$G$665:$G$673) -> 0 | R19: =SUMIF(Hitungan!$C$665:$C$673,"Pengurangan Dari Kejadian",Hitungan!$G$665:$G$673) -> 0 | S19: =SUMIF(Hitungan!$C$665:$C$673,"Pemotongan SP",Hitungan!$G$665:$G$673) -> 0 | T19: =SUMIF(Hitungan!$C$665:$C$673,"Kasbon",Hitungan!$G$665:$G$673) -> 0 | V19: =SUM(Q19:U19) -> 0 | W19: =SUMIF(Hitungan!$C$665:$C$673,"Service Charge",Hitungan!$G$665:$G$673) -> 367854 | X19: =M19-V19+W19 -> 3641854 | Y19: =ROUNDDOWN(X19,0) -> 3641854 | Z19: =D19 -> 1800000 | AA19: =Y19-Z19 -> 1841854 | AB19: - | AC19: SBB
A20: 18 | B20: Nurwahid | C20: KG | D20: =SUMIF(Hitungan!$C$746:$C$754,D$1,Hitungan!$G$746:$G$754) -> 354166.67 | E20: =SUMIF(Hitungan!$C$746:$C$754,E$1,Hitungan!$G$746:$G$754) -> 105000 | F20: =SUMIF(Hitungan!$C$746:$C$754,F$1,Hitungan!$G$746:$G$754) -> 145000 | G20: =SUMIF(Hitungan!$C$746:$C$754,G$1,Hitungan!$G$746:$G$754) -> 0 | H20: =SUMIF(Hitungan!$C$746:$C$754,H$1,Hitungan!$G$746:$G$754) -> 0 | I20: =SUMIF(Hitungan!$C$746:$C$754,I$1,Hitungan!$G$746:$G$754) -> 0 | J20: =SUMIF(Hitungan!$C$746:$C$754,J$1,Hitungan!$G$746:$G$754) -> 0 | K20: =SUMIF(Hitungan!$C$746:$C$754,K$1,Hitungan!$G$746:$G$754) -> 0 | L20: 500000 | M20: =SUM(D20:L20) -> 1104166.7 | N20: =SUMIF(Hitungan!$C$746:$C$754,"Uang Makan",Hitungan!$F$746:$F$754) -> 5 | O20: =IFERROR(M20/N20,"") -> 220833.33 | P20: =SUMIF(Hitungan!$C$746:$C$754,"Keterlambatan",Hitungan!$F$746:$F$754) -> 0 | Q20: =SUMIF(Hitungan!$C$746:$C$754,"Keterlambatan",Hitungan!$G$746:$G$754) -> 0 | R20: =SUMIF(Hitungan!$C$746:$C$754,"Pengurangan Dari Kejadian",Hitungan!$G$746:$G$754) -> 0 | S20: =SUMIF(Hitungan!$C$746:$C$754,"Pemotongan SP",Hitungan!$G$746:$G$754) -> 0 | T20: =SUMIF(Hitungan!$C$746:$C$754,"Kasbon",Hitungan!$G$746:$G$754) -> 0 | V20: =SUM(Q20:U20) -> 0 | W20: =SUMIF(Hitungan!$C$746:$C$754,"Service Charge",Hitungan!$G$746:$G$754) -> 80584 | X20: =M20-V20+W20 -> 1184750.7 | Y20: =ROUNDDOWN(X20,0) -> 1184750 | Z20: =Y20 -> 1184750 | AA20: =Y20-Z20-AB20 -> 0 | AB20: =H20 -> 0 | AC20: SBB
A21: 19 | B21: Rovi | C21: KG | D21: =SUMIF(Hitungan!$C$706:$C$714,D$1,Hitungan!$G$706:$G$714) -> 2250000 | E21: =SUMIF(Hitungan!$C$706:$C$714,E$1,Hitungan!$G$706:$G$714) -> 483000 | F21: =SUMIF(Hitungan!$C$706:$C$714,F$1,Hitungan!$G$706:$G$714) -> 920000 | G21: =SUMIF(Hitungan!$C$706:$C$714,G$1,Hitungan!$G$706:$G$714) -> 0 | H21: =SUMIF(Hitungan!$C$706:$C$714,H$1,Hitungan!$G$706:$G$714) -> 0 | I21: =SUMIF(Hitungan!$C$706:$C$714,I$1,Hitungan!$G$706:$G$714) -> 0 | J21: =SUMIF(Hitungan!$C$706:$C$714,J$1,Hitungan!$G$706:$G$714) -> 0 | K21: =SUMIF(Hitungan!$C$706:$C$714,K$1,Hitungan!$G$706:$G$714) -> 0 | M21: =SUM(D21:L21) -> 3653000 | N21: =SUMIF(Hitungan!$C$706:$C$714,"Uang Makan",Hitungan!$F$706:$F$714) -> 23 | O21: =IFERROR(M21/N21,"") -> 158826.09 | P21: =SUMIF(Hitungan!$C$706:$C$714,"Keterlambatan",Hitungan!$F$706:$F$714) -> 0 | Q21: =SUMIF(Hitungan!$C$706:$C$714,"Keterlambatan",Hitungan!$G$706:$G$714) -> 0 | R21: =SUMIF(Hitungan!$C$706:$C$714,"Pengurangan Dari Kejadian",Hitungan!$G$706:$G$714) -> 0 | S21: =SUMIF(Hitungan!$C$706:$C$714,"Pemotongan SP",Hitungan!$G$706:$G$714) -> 0 | T21: =SUMIF(Hitungan!$C$706:$C$714,"Kasbon",Hitungan!$G$706:$G$714) -> 0 | V21: =SUM(Q21:U21) -> 0 | W21: =SUMIF(Hitungan!$C$706:$C$714,"Service Charge",Hitungan!$G$706:$G$714) -> 334558 | X21: =M21-V21+W21 -> 3987558 | Y21: =ROUNDDOWN(X21,0) -> 3987558 | Z21: =D21 -> 2250000 | AA21: =Y21-Z21 -> 1737558 | AB21: - | AC21: SBB
A22: 20 | B22: Ferdy | C22: KG | D22: =SUMIF(Hitungan!$C$624:$C$632,D$1,Hitungan!$G$624:$G$632) -> 3190000 | E22: =SUMIF(Hitungan!$C$624:$C$632,E$1,Hitungan!$G$624:$G$632) -> 546000 | F22: =SUMIF(Hitungan!$C$624:$C$632,F$1,Hitungan!$G$624:$G$632) -> 1404000 | G22: =SUMIF(Hitungan!$C$624:$C$632,G$1,Hitungan!$G$624:$G$632) -> 0 | H22: =SUMIF(Hitungan!$C$624:$C$632,H$1,Hitungan!$G$624:$G$632) -> 45000 | I22: =SUMIF(Hitungan!$C$624:$C$632,I$1,Hitungan!$G$624:$G$632) -> 0 | J22: =SUMIF(Hitungan!$C$624:$C$632,J$1,Hitungan!$G$624:$G$632) -> 0 | K22: =SUMIF(Hitungan!$C$624:$C$632,K$1,Hitungan!$G$624:$G$632) -> 0 | M22: =SUM(D22:L22) -> 5185000 | N22: =SUMIF(Hitungan!$C$624:$C$632,"Uang Makan",Hitungan!$F$624:$F$632) -> 26 | O22: =IFERROR(M22/N22,"") -> 199423.08 | P22: =SUMIF(Hitungan!$C$624:$C$632,"Keterlambatan",Hitungan!$F$624:$F$632) -> 0 | Q22: =SUMIF(Hitungan!$C$624:$C$632,"Keterlambatan",Hitungan!$G$624:$G$632) -> 0 | R22: =SUMIF(Hitungan!$C$624:$C$632,"Pengurangan Dari Kejadian",Hitungan!$G$624:$G$632) -> 0 | S22: =SUMIF(Hitungan!$C$624:$C$632,"Pemotongan SP",Hitungan!$G$624:$G$632) -> 0 | T22: =SUMIF(Hitungan!$C$624:$C$632,"Kasbon",Hitungan!$G$624:$G$632) -> 0 | V22: =SUM(Q22:U22) -> 0 | W22: =SUMIF(Hitungan!$C$624:$C$632,"Service Charge",Hitungan!$G$624:$G$632) -> 389185 | X22: =M22-V22+W22 -> 5574185 | Y22: =ROUNDDOWN(X22,0) -> 5574185 | Z22: =D22 -> 3190000 | AA22: =Y22-Z22-AB22 -> 2384185 | AC22: SBB
A23: 21 | B23: Danilo | C23: KG | D23: =SUMIF(Hitungan!$C$910:$C$918,D$1,Hitungan!$G$910:$G$918) -> 241666.67 | E23: =SUMIF(Hitungan!$C$910:$C$918,E$1,Hitungan!$G$910:$G$918) -> 84000 | F23: =SUMIF(Hitungan!$C$910:$C$918,F$1,Hitungan!$G$910:$G$918) -> 140400 | G23: =SUMIF(Hitungan!$C$910:$C$918,G$1,Hitungan!$G$910:$G$918) -> 0 | H23: =SUMIF(Hitungan!$C$910:$C$918,H$1,Hitungan!$G$910:$G$918) -> 0 | I23: =SUMIF(Hitungan!$C$910:$C$918,I$1,Hitungan!$G$910:$G$918) -> 0 | J23: =SUMIF(Hitungan!$C$910:$C$918,J$1,Hitungan!$G$910:$G$918) -> 0 | K23: =SUMIF(Hitungan!$C$910:$C$918,K$1,Hitungan!$G$910:$G$918) -> 0 | L23: 500000 | M23: =SUM(D23:L23) -> 966066.67 | N23: =SUMIF(Hitungan!$C$910:$C$918,"Uang Makan",Hitungan!$F$910:$F$918) -> 4 | O23: =IFERROR(M23/N23,"") -> 241516.67 | P23: =SUMIF(Hitungan!$C$910:$C$918,"Keterlambatan",Hitungan!$F$910:$F$918) -> 0 | Q23: =SUMIF(Hitungan!$C$910:$C$918,"Keterlambatan",Hitungan!$G$910:$G$918) -> 0 | R23: =SUMIF(Hitungan!$C$910:$C$918,"Pengurangan Dari Kejadian",Hitungan!$G$910:$G$918) -> 0 | S23: =SUMIF(Hitungan!$C$910:$C$918,"Pemotongan SP",Hitungan!$G$910:$G$918) -> 0 | T23: =SUMIF(Hitungan!$C$910:$C$918,"Kasbon",Hitungan!$G$910:$G$918) -> 0 | V23: =SUM(Q23:U23) -> 0 | W23: =SUMIF(Hitungan!$C$910:$C$918,"Service Charge",Hitungan!$G$910:$G$918) -> 54178 | X23: =M23-V23+W23 -> 1020244.7 | Y23: =ROUNDDOWN(X23,0) -> 1020244 | Z23: =Y23 -> 1020244 | AA23: =Y23-Z23 -> 0 | AB23: - | AC23: SBB
A24: 22 | B24: Ridho | C24: KG | D24: =SUMIF(Hitungan!$C$951:$C$959,D$1,Hitungan!$G$951:$G$959) -> 0 | E24: =SUMIF(Hitungan!$C$951:$C$959,E$1,Hitungan!$G$951:$G$959) -> 0 | F24: =SUMIF(Hitungan!$C$951:$C$959,F$1,Hitungan!$G$951:$G$959) -> 0 | G24: =SUMIF(Hitungan!$C$951:$C$959,G$1,Hitungan!$G$951:$G$959) -> 0 | H24: =SUMIF(Hitungan!$C$951:$C$959,H$1,Hitungan!$G$951:$G$959) -> 0 | I24: =SUMIF(Hitungan!$C$951:$C$959,I$1,Hitungan!$G$951:$G$959) -> 0 | J24: =SUMIF(Hitungan!$C$951:$C$959,J$1,Hitungan!$G$951:$G$959) -> 0 | K24: =SUMIF(Hitungan!$C$951:$C$959,K$1,Hitungan!$G$951:$G$959) -> 1500000 | M24: =SUM(D24:L24) -> 1500000 | N24: =SUMIF(Hitungan!$C$951:$C$959,"Uang Makan",Hitungan!$F$951:$F$959) -> 10 | O24: =IFERROR(M24/N24,"") -> 150000 | P24: =SUMIF(Hitungan!$C$951:$C$959,"Keterlambatan",Hitungan!$F$951:$F$959) -> 0 | Q24: =SUMIF(Hitungan!$C$951:$C$959,"Keterlambatan",Hitungan!$G$951:$G$959) -> 0 | R24: =SUMIF(Hitungan!$C$951:$C$959,"Pengurangan Dari Kejadian",Hitungan!$G$951:$G$959) -> 0 | S24: =SUMIF(Hitungan!$C$951:$C$959,"Pemotongan SP",Hitungan!$G$951:$G$959) -> 0 | T24: =SUMIF(Hitungan!$C$951:$C$959,"Kasbon",Hitungan!$G$951:$G$959) -> 0 | V24: =SUM(Q24:U24) -> 0 | W24: =SUMIF(Hitungan!$C$951:$C$959,"Service Charge",Hitungan!$G$951:$G$959) -> 0 | X24: =M24-V24+W24 -> 1500000 | Y24: =ROUNDDOWN(X24,0) -> 1500000 | Z24: =D24 -> 0 | AA24: =Y24-Z24 -> 1500000 | AB24: - | AC24: SBB
A25: 23 | B25: Rifki | C25: KG | D25: =SUMIF(Hitungan!$C$869:$C$877,D$1,Hitungan!$G$869:$G$877) -> 1740000 | E25: =SUMIF(Hitungan!$C$869:$C$877,E$1,Hitungan!$G$869:$G$877) -> 504000 | F25: =SUMIF(Hitungan!$C$869:$C$877,F$1,Hitungan!$G$869:$G$877) -> 939600 | G25: =SUMIF(Hitungan!$C$869:$C$877,G$1,Hitungan!$G$869:$G$877) -> 0 | H25: =SUMIF(Hitungan!$C$869:$C$877,H$1,Hitungan!$G$869:$G$877) -> 0 | I25: =SUMIF(Hitungan!$C$869:$C$877,I$1,Hitungan!$G$869:$G$877) -> 0 | J25: =SUMIF(Hitungan!$C$869:$C$877,J$1,Hitungan!$G$869:$G$877) -> 0 | K25: =SUMIF(Hitungan!$C$869:$C$877,K$1,Hitungan!$G$869:$G$877) -> 0 | M25: =SUM(D25:L25) -> 3183600 | N25: =SUMIF(Hitungan!$C$869:$C$877,"Uang Makan",Hitungan!$F$869:$F$877) -> 24 | O25: =IFERROR(M25/N25,"") -> 132650 | P25: =SUMIF(Hitungan!$C$869:$C$877,"Keterlambatan",Hitungan!$F$869:$F$877) -> 0 | Q25: =SUMIF(Hitungan!$C$869:$C$877,"Keterlambatan",Hitungan!$G$869:$G$877) -> 0 | R25: =SUMIF(Hitungan!$C$869:$C$877,"Pengurangan Dari Kejadian",Hitungan!$G$869:$G$877) -> 0 | S25: =SUMIF(Hitungan!$C$869:$C$877,"Pemotongan SP",Hitungan!$G$869:$G$877) -> 0 | T25: =SUMIF(Hitungan!$C$869:$C$877,"Kasbon",Hitungan!$G$869:$G$877) -> 0 | V25: =SUM(Q25:U25) -> 0 | W25: =SUMIF(Hitungan!$C$869:$C$877,"Service Charge",Hitungan!$G$869:$G$877) -> 352835 | X25: =M25-V25+W25 -> 3536435 | Y25: =ROUNDDOWN(X25,0) -> 3536435 | AA25: =Y25-Z25 -> 3536435 | AB25: - | AC25: SBB
A26: 24 | B26: Revan | C26: KG | D26: =SUMIF(Hitungan!$C$1033:$C$1041,D$1,Hitungan!$G$1033:$G$1041) -> 870000 | E26: =SUMIF(Hitungan!$C$1033:$C$1041,E$1,Hitungan!$G$1033:$G$1041) -> 252000 | F26: =SUMIF(Hitungan!$C$1033:$C$1041,F$1,Hitungan!$G$1033:$G$1041) -> 469800 | G26: =SUMIF(Hitungan!$C$1033:$C$1041,G$1,Hitungan!$G$1033:$G$1041) -> 0 | H26: =SUMIF(Hitungan!$C$1033:$C$1041,H$1,Hitungan!$G$1033:$G$1041) -> 0 | I26: =SUMIF(Hitungan!$C$1033:$C$1041,I$1,Hitungan!$G$1033:$G$1041) -> 0 | J26: =SUMIF(Hitungan!$C$1033:$C$1041,J$1,Hitungan!$G$1033:$G$1041) -> 0 | K26: =SUMIF(Hitungan!$C$1033:$C$1041,K$1,Hitungan!$G$1033:$G$1041) -> 0 | M26: =SUM(D26:L26) -> 1591800 | N26: =SUMIF(Hitungan!$C$1033:$C$1041,"Uang Makan",Hitungan!$F$1033:$F$1041) -> 12 | O26: =IFERROR(M26/N26,"") -> 132650 | P26: =SUMIF(Hitungan!$C$1033:$C$1041,"Keterlambatan",Hitungan!$F$1033:$F$1041) -> 0 | Q26: =SUMIF(Hitungan!$C$1033:$C$1041,"Keterlambatan",Hitungan!$G$1033:$G$1041) -> 0 | R26: =SUMIF(Hitungan!$C$1033:$C$1041,"Pengurangan Dari Kejadian",Hitungan!$G$1033:$G$1041) -> 35000 | S26: =SUMIF(Hitungan!$C$1033:$C$1041,"Pemotongan SP",Hitungan!$G$1033:$G$1041) -> 0 | T26: =SUMIF(Hitungan!$C$1033:$C$1041,"Kasbon",Hitungan!$G$1033:$G$1041) -> 0 | V26: =SUM(Q26:U26) -> 35000 | W26: =SUMIF(Hitungan!$C$1033:$C$1041,"Service Charge",Hitungan!$G$1033:$G$1041) -> 152157 | X26: =M26-V26+W26 -> 1708957 | Y26: =ROUNDDOWN(X26,0) -> 1708957 | AA26: =Y26-Z26 -> 1708957 | AB26: - | AC26: SBB
A27: 25 | B27: Andri | C27: KG | D27: =(1740000/24)*3 -> 217500 | E27: =21000*3 -> 63000 | F27: =39150*3 -> 117450 | M27: =SUM(D27:L27) -> 397950 | N27: 3 | Y27: =M27 -> 397950 | AA27: =M27 -> 397950
A28: 25 | B28: Bulan | C28: Fatgai | D28: =SUMIF(Hitungan!$C$542:$C$550,D$1,Hitungan!$G$542:$G$550) -> 2250000 | E28: =SUMIF(Hitungan!$C$542:$C$550,E$1,Hitungan!$G$542:$G$550) -> 819000 | F28: =SUMIF(Hitungan!$C$542:$C$550,F$1,Hitungan!$G$542:$G$550) -> 1482000 | G28: =SUMIF(Hitungan!$C$542:$C$550,G$1,Hitungan!$G$542:$G$550) -> 0 | H28: =SUMIF(Hitungan!$C$542:$C$550,H$1,Hitungan!$G$542:$G$550) -> 0 | I28: =SUMIF(Hitungan!$C$542:$C$550,I$1,Hitungan!$G$542:$G$550) -> 0 | J28: =SUMIF(Hitungan!$C$542:$C$550,J$1,Hitungan!$G$542:$G$550) -> 0 | K28: =SUMIF(Hitungan!$C$542:$C$550,K$1,Hitungan!$G$542:$G$550) -> 0 | M28: =SUM(D28:L28) -> 4551000 | N28: =SUMIF(Hitungan!$C$542:$C$550,"Uang Makan",Hitungan!$F$542:$F$550) -> 26 | O28: =IFERROR(M28/N28,"") -> 175038.46 | P28: =SUMIF(Hitungan!$C$542:$C$550,"Keterlambatan",Hitungan!$F$542:$F$550) -> 2 | Q28: =SUMIF(Hitungan!$C$542:$C$550,"Keterlambatan",Hitungan!$G$542:$G$550) -> 38000 | R28: =SUMIF(Hitungan!$C$542:$C$550,"Pengurangan Dari Kejadian",Hitungan!$G$542:$G$550) -> 0 | S28: =SUMIF(Hitungan!$C$542:$C$550,"Pemotongan SP",Hitungan!$G$542:$G$550) -> 0 | T28: =SUMIF(Hitungan!$C$542:$C$550,"Kasbon",Hitungan!$G$542:$G$550) -> 0 | V28: =SUM(Q28:U28) -> 38000 | W28: =SUMIF(Hitungan!$C$542:$C$550,"Service Charge",Hitungan!$G$542:$G$550) -> 217181 | X28: =M28-V28+W28 -> 4730181 | Y28: =ROUNDDOWN(X28,0) -> 4730181 | Z28: =D28 -> 2250000 | AA28: =Y28-Z28 -> 2480181 | AC28: SBR
A29: 26 | B29: Sanusi | C29: Fatgai | D29: =SUMIF(Hitungan!$C$583:$C$591,D$1,Hitungan!$G$583:$G$591) -> 1740000 | E29: =SUMIF(Hitungan!$C$583:$C$591,E$1,Hitungan!$G$583:$G$591) -> 546000 | F29: =SUMIF(Hitungan!$C$583:$C$591,F$1,Hitungan!$G$583:$G$591) -> 1017900 | G29: =SUMIF(Hitungan!$C$583:$C$591,G$1,Hitungan!$G$583:$G$591) -> 0 | H29: =SUMIF(Hitungan!$C$583:$C$591,H$1,Hitungan!$G$583:$G$591) -> 0 | I29: =SUMIF(Hitungan!$C$583:$C$591,I$1,Hitungan!$G$583:$G$591) -> 0 | J29: =SUMIF(Hitungan!$C$583:$C$591,J$1,Hitungan!$G$583:$G$591) -> 0 | K29: =SUMIF(Hitungan!$C$583:$C$591,K$1,Hitungan!$G$583:$G$591) -> 0 | M29: =SUM(D29:L29) -> 3303900 | N29: =SUMIF(Hitungan!$C$583:$C$591,"Uang Makan",Hitungan!$F$583:$F$591) -> 26 | O29: =IFERROR(M29/N29,"") -> 127073.08 | P29: =SUMIF(Hitungan!$C$583:$C$591,"Keterlambatan",Hitungan!$F$583:$F$591) -> 2 | Q29: =SUMIF(Hitungan!$C$583:$C$591,"Keterlambatan",Hitungan!$G$583:$G$591) -> 26100 | R29: =SUMIF(Hitungan!$C$583:$C$591,"Pengurangan Dari Kejadian",Hitungan!$G$583:$G$591) -> 0 | S29: =SUMIF(Hitungan!$C$583:$C$591,"Pemotongan SP",Hitungan!$G$583:$G$591) -> 0 | T29: =SUMIF(Hitungan!$C$583:$C$591,"Kasbon",Hitungan!$G$583:$G$591) -> 0 | U29: 250000 | V29: =SUM(Q29:U29) -> 276100 | W29: =SUMIF(Hitungan!$C$583:$C$591,"Service Charge",Hitungan!$G$583:$G$591) -> 217181 | X29: =M29-V29+W29 -> 3244981 | Y29: =ROUNDDOWN(X29,0) -> 3244981 | Z29: =D29-V29 -> 1463900 | AA29: =Y29-Z29 -> 1781081 | AB29: - | AC29: SBR
A30: 27 | B30: Fanny | C30: Fatgai | D30: =SUMIF(Hitungan!$C$1074:$C$1082,D$1,Hitungan!$G$1074:$G$1082) -> 677875 | E30: =SUMIF(Hitungan!$C$1074:$C$1082,E$1,Hitungan!$G$1074:$G$1082) -> 196350 | F30: =SUMIF(Hitungan!$C$1074:$C$1082,F$1,Hitungan!$G$1074:$G$1082) -> 366058 | G30: =SUMIF(Hitungan!$C$1074:$C$1082,G$1,Hitungan!$G$1074:$G$1082) -> 0 | H30: =SUMIF(Hitungan!$C$1074:$C$1082,H$1,Hitungan!$G$1074:$G$1082) -> 0 | I30: =SUMIF(Hitungan!$C$1074:$C$1082,I$1,Hitungan!$G$1074:$G$1082) -> 0 | J30: =SUMIF(Hitungan!$C$1074:$C$1082,J$1,Hitungan!$G$1074:$G$1082) -> 0 | K30: =SUMIF(Hitungan!$C$1074:$C$1082,K$1,Hitungan!$G$1074:$G$1082) -> 0 | M30: =SUM(D30:L30) -> 1240283 | N30: =SUMIF(Hitungan!$C$1074:$C$1082,"Uang Makan",Hitungan!$F$1074:$F$1082) -> 11 | O30: =IFERROR(M30/N30,"") -> 112753 | P30: =SUMIF(Hitungan!$C$1074:$C$1082,"Keterlambatan",Hitungan!$F$1074:$F$1082) -> 0 | Q30: =SUMIF(Hitungan!$C$1074:$C$1082,"Keterlambatan",Hitungan!$G$1074:$G$1082) -> 0 | R30: =SUMIF(Hitungan!$C$1074:$C$1082,"Pengurangan Dari Kejadian",Hitungan!$G$1074:$G$1082) -> 0 | S30: =SUMIF(Hitungan!$C$1074:$C$1082,"Pemotongan SP",Hitungan!$G$1074:$G$1082) -> 0 | T30: =SUMIF(Hitungan!$C$1074:$C$1082,"Kasbon",Hitungan!$G$1074:$G$1082) -> 0 | V30: =SUM(Q30:U30) -> 0 | W30: =SUMIF(Hitungan!$C$1074:$C$1082,"Service Charge",Hitungan!$G$1074:$G$1082) -> 124258 | X30: =M30-V30+W30 -> 1364541 | Y30: =ROUNDDOWN(X30,0) -> 1364541 | AA30: =Y30-Z30 -> 1364541 | AB30: - | AC30: SBR
A31: 28 | B31: Wahidin | C31: Fatgai | D31: =(1479000/24)*4 -> 246500 | E31: =17850*4 -> 71400 | F31: =33278*4 -> 133112 | M31: =SUM(D31:L31) -> 451012 | AA31: 451012
B32: TOTAL | D32: =SUM(D2:D30) -> 39801929 | E32: =SUM(E2:E30) -> 12003725 | F32: =SUM(F2:F30) -> 21408183 | G32: =SUM(G2:G30) -> 0 | H32: =SUM(H2:H30) -> 82166.667 | I32: =SUM(I2:I30) -> 0 | J32: =SUM(J2:J30) -> 0 | K32: =SUM(K2:K30) -> 4650000 | ... Y32: =SUM(Y2:Y30) -> 83340720 | Z32: =sum(Z2:Z31) -> 33414615 | AA32: =sum(AA2:AA31) -> 50602117
R33: Cek SUM Service Charge | S33: Diff
Q34: GS | R34: =SUMIFS($W:$W,$C:$C,Q34) -> 4095319 | S34: DATA BELUM TERSEDIA
Q35: KG | R35: =SUMIFS($W:$W,$C:$C,Q35) -> 2392797 | S35: DATA BELUM TERSEDIA
Q37: Transfer tgl 25 | R37: WP | S37: Template FLIP | T37: Diff
Q38: GS | R38: =SUMIFS($Y:$Y,$C:$C,Q38) -> 31403752 | S38: 18871798 | T38: =R38-S38 -> 12531954
Q39: KG | R39: =SUMIFS($Y:$Y,$C:$C,Q39) -> 31145712 | S39: 15580214 | T39: =R39-S39 -> 15565498

Sheet Payslip GS, KG Joglo
I1: Nama | J1: Outlet | K1: Nomor Rekening | L1: Nama di rekening | M1: Bank | N1: Kode Bank FLIP
B2: CRACKLING | H2: 1 | I2: Renaldi | J2: Joglo | K2: 2880127091 | L2: Renaldi Leo tarigan | M2: BCA
B3: {=INDEX('Panduan Gaji'!$Q:$Q,MATCH($D$6,'Panduan Gaji'!C:C,0))} -> GS | H3: =H2+1 -> 2 | I3: Ano | J3: Joglo
B4: =TODAY() -> 46262 | H4: =H3+1 -> 3 | I4: Raihan | J4: Joglo
H5: =H4+1 -> 4 | I5: Teguh | J5: Joglo
B6: Nama | D6: {=INDEX($I:$I,MATCH(D7,$H:$H,0))} -> Made | H6: =H5+1 -> 5 | I6: Titus | J6: GS | K6: 7485351451 | L6: Titus Wegi Ziraluo | M6: BCA
B7: No Karyawan | D7: 14 | H7: =H6+1 -> 6 | I7: Sekar | J7: GS | K7: 6041421310 | L7: Sekar Mayang Febri Rahayu | M7: BCA
B8: Jenis Gaji | C8: Jumlah | D8: Kalkulasi | E8: Total | H8: =H7+1 -> 7 | I8: Ahmad | J8: GS | K8: 5205037915 | L8: Ahmad Yani | M8: BCA
B9: Gaji Pokok | C9: =SUMIFS(Hitungan!$F:$F,Hitungan!$C:$C,'Payslip GS, KG Joglo'!B9,Hitungan!$D:$D,'Payslip GS, KG Joglo'!$D$6) -> 1 | D9: =IFERROR(E9/C9,0) -> 1377500 | E9: =SUMIFS(Hitungan!$G:$G,Hitungan!$C:$C,'Payslip GS, KG Joglo'!B9,Hitungan!$D:$D,'Payslip GS, KG Joglo'!D$6) -> 1377500 | H9: =H8+1 -> 8 | I9: Valen | J9: GS | K9: 1082457989 | L9: Valentino Kurniawan | M9: BCA
B10: Gaji Harian | C10: =SUMIFS(Hitungan!$F:$F,Hitungan!$C:$C,'Payslip GS, KG Joglo'!B10,Hitungan!$D:$D,'Payslip GS, KG Joglo'!$D$6) -> 0 | D10: =IFERROR(E10/C10,0) -> 0 | E10: =SUMIFS(Hitungan!$G:$G,Hitungan!$C:$C,'Payslip GS, KG Joglo'!B10,Hitungan!$D:$D,'Payslip GS, KG Joglo'!D$6) -> 0 | H10: =H9+1 -> 9 | I10: Rifai | J10: GS
B11: Gaji Per Jam | C11: =SUMIFS(Hitungan!$F:$F,Hitungan!$C:$C,'Payslip GS, KG Joglo'!B11,Hitungan!$D:$D,'Payslip GS, KG Joglo'!$D$6) -> 0 | D11: =IFERROR(E11/C11,0) -> 0 | E11: =SUMIFS(Hitungan!$G:$G,Hitungan!$C:$C,'Payslip GS, KG Joglo'!B11,Hitungan!$D:$D,'Payslip GS, KG Joglo'!D$6) -> 0 | H11: =H10+1 -> 10 | I11: Audy | J11: GS
B12: Service Charge | C12: =SUMIFS(Hitungan!$F:$F,Hitungan!$C:$C,'Payslip GS, KG Joglo'!B12,Hitungan!$D:$D,'Payslip GS, KG Joglo'!$D$6) -> 1 | D12: =SUMIFS(Hitungan!E:E,Hitungan!D:D,'Payslip GS, KG Joglo'!D6,Hitungan!C:C,"Service Charge") -> 321766 | E12: =C12*D12 -> 321766 | H12: =H11+1 -> 11 | I12: Wise | J12: GS | K12: 8832380481 | L12: Wise Mariana Bulan | M12: BCA
B13: Uang Transport | C13: =SUMIFS(Hitungan!$F:$F,Hitungan!$C:$C,'Payslip GS, KG Joglo'!B13,Hitungan!$D:$D,'Payslip GS, KG Joglo'!$D$6) -> 19 | D13: =IFERROR(E13/C13,0) -> 21000 | E13: =SUMIFS(Hitungan!$G:$G,Hitungan!$C:$C,'Payslip GS, KG Joglo'!B13,Hitungan!$D:$D,'Payslip GS, KG Joglo'!D$6) -> 399000 | H13: =H12+1 -> 12 | I13: Nur Andika | J13: GS | K13: 7263026111 | L13: Nur Muhamad Andika | M13: BCA
B14: Uang Makan | C14: =SUMIFS(Hitungan!$F:$F,Hitungan!$C:$C,'Payslip GS, KG Joglo'!B14,Hitungan!$D:$D,'Payslip GS, KG Joglo'!$D$6) -> 19 | D14: =IFERROR(E14/C14,0) -> 39150 | E14: =SUMIFS(Hitungan!$G:$G,Hitungan!$C:$C,'Payslip GS, KG Joglo'!B14,Hitungan!$D:$D,'Payslip GS, KG Joglo'!D$6) -> 743850 | H14: =H13+1 -> 13 | I14: Jerrel | J14: GS
B15: Bonus | C15: =SUMIFS(Hitungan!$F:$F,Hitungan!$C:$C,'Payslip GS, KG Joglo'!B15,Hitungan!$D:$D,'Payslip GS, KG Joglo'!$D$6) -> 0 | D15: =IFERROR(E15/C15,0) -> 0 | E15: =SUMIFS(Hitungan!$G:$G,Hitungan!$C:$C,'Payslip GS, KG Joglo'!B15,Hitungan!$D:$D,'Payslip GS, KG Joglo'!D$6) -> 0 | H15: =H14+1 -> 14 | I15: Made | J15: GS
B16: Lembur | C16: =SUMIFS(Hitungan!$F:$F,Hitungan!$C:$C,'Payslip GS, KG Joglo'!B16,Hitungan!$D:$D,'Payslip GS, KG Joglo'!$D$6) -> 0 | D16: =IFERROR(E16/C16,0) -> 0 | E16: =SUMIFS(Hitungan!$G:$G,Hitungan!$C:$C,'Payslip GS, KG Joglo'!B16,Hitungan!$D:$D,'Payslip GS, KG Joglo'!D$6) -> 0 | H16: =H15+1 -> 15 | I16: Irvan | J16: KG | K16: 4910610860 | L16: Irvan Putra Sondrorogo | M16: BCA
B17: Deposit | H17: =H16+1 -> 16 | I17: Rizky | J17: KG | K17: 6430268323 | L17: Rizky Maulana | M17: BCA
B18: Total | E18: =SUM(E9:E17) -> 2842116 | H18: =H17+1 -> 17 | I18: Sabrina | J18: KG | K18: 0070991691 | L18: Sabrina Nurhaliza | M18: BCA
H19: =H18+1 -> 18 | I19: Nurwahid | J19: KG | K19: 901445613594 | L19: Muhamad Nurwahid | M19: Seabank
B20: Potongan | H20: =H19+1 -> 19 | I20: Rovi | J20: KG | K20: 1790386872 | L20: M.Rovi Hakiki Samsi | M20: BCA
B21: Keterlambatan | C21: =IFERROR(E21/D21,0) -> 13050 | D21: =SUMIFS(Hitungan!$F:$F,Hitungan!$D:$D,'Payslip GS, KG Joglo'!$D$6,Hitungan!$C:$C,'Payslip GS, KG Joglo'!B21) -> 2 | E21: =SUMIFS(Hitungan!$G:$G,Hitungan!$C:$C,'Payslip GS, KG Joglo'!B21,Hitungan!$D:$D,'Payslip GS, KG Joglo'!$D$6) -> 26100 | H21: =H20+1 -> 20 | I21: Ferdy | J21: KG | K21: 4610662485 | L21: Ferdyansah Agus Saputra | M21: BCA
B22: Fasilitas Mess | C22: =IFERROR(E22/D22,0) -> 0 | D22: =SUMIFS(Hitungan!$F:$F,Hitungan!$D:$D,'Payslip GS, KG Joglo'!$D$6,Hitungan!$C:$C,'Payslip GS, KG Joglo'!B22) -> 0 | E22: =SUMIFS(Hitungan!$G:$G,Hitungan!$C:$C,'Payslip GS, KG Joglo'!B22,Hitungan!$D:$D,'Payslip GS, KG Joglo'!$D$6) -> 0 | H22: =H21+1 -> 21 | I22: Danilo | J22: KG | K22: 901969011802 | L22: Danilo Fernando | M22: Seabank
B23: Pengurangan Dari Kejadian | C23: =IFERROR(E23/D23,0) -> 76333.333 | D23: =SUMIFS(Hitungan!$F:$F,Hitungan!$D:$D,'Payslip GS, KG Joglo'!$D$6,Hitungan!$C:$C,'Payslip GS, KG Joglo'!B23) -> 6 | E23: =SUMIFS(Hitungan!$G:$G,Hitungan!$C:$C,'Payslip GS, KG Joglo'!B23,Hitungan!$D:$D,'Payslip GS, KG Joglo'!$D$6) -> 458000 | H23: =H22+1 -> 22 | I23: Ridho | J23: KG | K23: 901941347552 | L23: Ridho Ananta | M23: BCA
B24: Kasbon | C24: =IFERROR(E24/D24,0) -> 0 | D24: =SUMIFS(Hitungan!$F:$F,Hitungan!$D:$D,'Payslip GS, KG Joglo'!$D$6,Hitungan!$C:$C,'Payslip GS, KG Joglo'!B24) -> 0 | E24: =SUMIFS(Hitungan!$G:$G,Hitungan!$C:$C,'Payslip GS, KG Joglo'!B24,Hitungan!$D:$D,'Payslip GS, KG Joglo'!$D$6) -> 0 | H24: =H23+1 -> 23 | I24: Rifki | J24: KG
B25: Total Potongan | E25: =-SUM(E20:E24) -> -484100 | H25: =H24+1 -> 24 | I25: Revan | J25: KG
B27: Total | E27: =ROUNDDOWN(E18+E25,0) -> 2358016
B29: Transfer 10/6/2026 | E29: =D9 -> 1377500
B30: Transfer 25/6/2026 | E30: =E27-E29 -> 980516

Sheet Hitungan
A1: Kode | B1: Tanggal | C1: Jenis | D1: Nama | E1: Rate Harian | F1: Kehadiran | G1: Total Gaji | H1: Outlet | I1: Jadwal | J1: Masuk | K1: Pulang | L1: Keterangan
A2: 1 | C2: Gaji Pokok | D2: Renaldi | E2: =SUMIFS(SSOD!$C:$C,SSOD!$B:$B,Hitungan!D2,SSOD!$A:$A,Hitungan!C2) -> 1260000 | F2: 1 | G2: =E2*F2 -> 1260000 | H2: {=INDEX('Panduan Gaji'!$Q:$Q,MATCH(D2,'Panduan Gaji'!$C:$C,0))} -> Joglo
A3: =A2 -> 1 | C3: Gaji Harian | D3: =D2 -> Renaldi | E3: =SUMIFS(SSOD!$C:$C,SSOD!$B:$B,Hitungan!D3,SSOD!$A:$A,Hitungan!C3) -> 0 | G3: =E3*F3 -> 0 | H3: {=INDEX('Panduan Gaji'!$Q:$Q,MATCH(D3,'Panduan Gaji'!$C:$C,0))} -> Joglo
A4: =A3 -> 1 | C4: Uang Transport | D4: =D3 -> Renaldi | E4: =SUMIFS(SSOD!$C:$C,SSOD!$B:$B,Hitungan!D4,SSOD!$A:$A,Hitungan!C4) -> 65000 | F4: =SUMPRODUCT(--((($J$11:$J$41<>"")+($K$11:$K$41<>""))>0)) -> 25 | G4: =E4*F4 -> 1625000 | H4: {=INDEX('Panduan Gaji'!$Q:$Q,MATCH(D4,'Panduan Gaji'!$C:$C,0))} -> Joglo
A5: =A4 -> 1 | C5: Uang Makan | D5: =D4 -> Renaldi | E5: =SUMIFS(SSOD!$C:$C,SSOD!$B:$B,Hitungan!D5,SSOD!$A:$A,Hitungan!C5) -> 57500 | F5: =SUMPRODUCT(--((($J$11:$J$41<>"")+($K$11:$K$41<>""))>0))+1 -> 26 | G5: =E5*F5 -> 1495000 | H5: {=INDEX('Panduan Gaji'!$Q:$Q,MATCH(D5,'Panduan Gaji'!$C:$C,0))} -> Joglo | I5: 17an dpt uang makan
A6: =A5 -> 1 | C6: Lembur | D6: =D5 -> Renaldi | E6: =SUMIFS(SSOD!$C:$C,SSOD!$B:$B,Hitungan!D6,SSOD!$A:$A,Hitungan!C6) -> 19166.667 | F6: =SUMIF($C$11:$C$41,C6,$F$11:$F$41) -> 1 | G6: =E6*F6 -> 19166.667 | H6: {=INDEX('Panduan Gaji'!$Q:$Q,MATCH(D6,'Panduan Gaji'!$C:$C,0))} -> Joglo
A7: =A6 -> 1 | C7: Keterlambatan | D7: =D6 -> Renaldi | E7: =SUMIFS(SSOD!$C:$C,SSOD!$B:$B,Hitungan!D7,SSOD!$A:$A,Hitungan!C7) -> 19166.667 | F7: =COUNTIF($C$11:$C$41,C7) -> 2 | G7: =E7*F7 -> 38333.333 | H7: {=INDEX('Panduan Gaji'!$Q:$Q,MATCH(D7,'Panduan Gaji'!$C:$C,0))} -> Joglo
A8: =A7 -> 1 | C8: Pengurangan Dari Kejadian | D8: =D7 -> Renaldi | F8: =COUNTIF($C$11:$C$41,C8) -> 1 | G8: =SUMIF($C$11:$C$41,C8,$E$11:$E$41) -> 15000 | H8: {=INDEX('Panduan Gaji'!$Q:$Q,MATCH(D8,'Panduan Gaji'!$C:$C,0))} -> Joglo
A9: =A8 -> 1 | C9: Pemotongan SP | D9: =D8 -> Renaldi | H9: {=INDEX('Panduan Gaji'!$Q:$Q,MATCH(D9,'Panduan Gaji'!$C:$C,0))} -> Joglo
A10: =A9 -> 1 | C10: Deposit | D10: =D9 -> Renaldi | H10: {=INDEX('Panduan Gaji'!$Q:$Q,MATCH(D10,'Panduan Gaji'!$C:$C,0))} -> Joglo
A11: =A10 -> 1 | B11: 46228 | D11: =D10 -> Renaldi | E11: =SUMIFS(SSOD!$C:$C,SSOD!$B:$B,Hitungan!D11,SSOD!$A:$A,Hitungan!C11) -> 0 | G11: =E11*F11 -> 0 | H11: {=INDEX('Panduan Gaji'!$Q:$Q,MATCH(D11,'Panduan Gaji'!$C:$C,0))} -> Joglo | I11: 08 s.d 20 | J11: 0.33541667 | K11: 0.625
A12: =A11 -> 1 | B12: 46229 | D12: =D11 -> Renaldi | E12: =SUMIFS(SSOD!$C:$C,SSOD!$B:$B,Hitungan!D12,SSOD!$A:$A,Hitungan!C12) -> 0 | G12: =E12*F12 -> 0 | H12: {=INDEX('Panduan Gaji'!$Q:$Q,MATCH(D12,'Panduan Gaji'!$C:$C,0))} -> Joglo | I12: 08 s.d 20
A13: =A12 -> 1 | B13: 46230 | D13: =D12 -> Renaldi | E13: =SUMIFS(SSOD!$C:$C,SSOD!$B:$B,Hitungan!D13,SSOD!$A:$A,Hitungan!C13) -> 0 | G13: =E13*F13 -> 0 | H13: {=INDEX('Panduan Gaji'!$Q:$Q,MATCH(D13,'Panduan Gaji'!$C:$C,0))} -> Joglo | I13: 08 s.d 20 | J13: 0.33402778 | K13: 0.84236111
A14: =A13 -> 1 | B14: 46231 | D14: =D13 -> Renaldi | E14: =SUMIFS(SSOD!$C:$C,SSOD!$B:$B,Hitungan!D14,SSOD!$A:$A,Hitungan!C14) -> 0 | G14: =E14*F14 -> 0 | H14: {=INDEX('Panduan Gaji'!$Q:$Q,MATCH(D14,'Panduan Gaji'!$C:$C,0))} -> Joglo | I14: 08 s.d 20 | J14: 0.33541667 | K14: 0.8375
A15: =A14 -> 1 | B15: 46232 | D15: =D14 -> Renaldi | E15: =SUMIFS(SSOD!$C:$C,SSOD!$B:$B,Hitungan!D15,SSOD!$A:$A,Hitungan!C15) -> 0 | G15: =E15*F15 -> 0 | H15: {=INDEX('Panduan Gaji'!$Q:$Q,MATCH(D15,'Panduan Gaji'!$C:$C,0))} -> Joglo | I15: 08 s.d 20 | J15: 0.32777778 | K15: 0.85208333
A16: =A15 -> 1 | B16: 46233 | D16: =D15 -> Renaldi | E16: =SUMIFS(SSOD!$C:$C,SSOD!$B:$B,Hitungan!D16,SSOD!$A:$A,Hitungan!C16) -> 0 | G16: =E16*F16 -> 0 | H16: {=INDEX('Panduan Gaji'!$Q:$Q,MATCH(D16,'Panduan Gaji'!$C:$C,0))} -> Joglo | I16: 08 s.d 20 | J16: 0.33333333 | K16: 0.84236111
A17: =A16 -> 1 | B17: 46234 | D17: =D16 -> Renaldi | E17: =SUMIFS(SSOD!$C:$C,SSOD!$B:$B,Hitungan!D17,SSOD!$A:$A,Hitungan!C17) -> 0 | G17: =E17*F17 -> 0 | H17: {=INDEX('Panduan Gaji'!$Q:$Q,MATCH(D17,'Panduan Gaji'!$C:$C,0))} -> Joglo | I17: 08 s.d 20 | J17: 0.33194444 | K17: 0.86319444
A18: =A17 -> 1 | B18: 46235 | D18: =D17 -> Renaldi | E18: 0 | G18: =E18*F18 -> 0 | H18: {=INDEX('Panduan Gaji'!$Q:$Q,MATCH(D18,'Panduan Gaji'!$C:$C,0))} -> Joglo | I18: 08 s.d 20 | J18: 0.33333333 | K18: 0.84166667
A19: =A18 -> 1 | B19: 46236 | D19: =D18 -> Renaldi | E19: =SUMIFS(SSOD!$C:$C,SSOD!$B:$B,Hitungan!D19,SSOD!$A:$A,Hitungan!C19) -> 0 | G19: =E19*F19 -> 0 | H19: {=INDEX('Panduan Gaji'!$Q:$Q,MATCH(D19,'Panduan Gaji'!$C:$C,0))} -> Joglo | I19: 08 s.d 20
A20: =A19 -> 1 | B20: 46237 | C20: Pengurangan Dari Kejadian | D20: =D19 -> Renaldi | E20: 15000 | F20: 1 | G20: =E20*F20 -> 15000 | H20: {=INDEX('Panduan Gaji'!$Q:$Q,MATCH(D20,'Panduan Gaji'!$C:$C,0))} -> Joglo | I20: 08 s.d 20 | J20: 0.33472222 | K20: 0.85416667 | L20: Hekeng Rusak
A21: =A20 -> 1 | B21: 46238 | D21: =D20 -> Renaldi | E21: =SUMIFS(SSOD!$C:$C,SSOD!$B:$B,Hitungan!D21,SSOD!$A:$A,Hitungan!C21) -> 0 | G21: =E21*F21 -> 0 | H21: {=INDEX('Panduan Gaji'!$Q:$Q,MATCH(D21,'Panduan Gaji'!$C:$C,0))} -> Joglo | I21: 08 s.d 20 | J21: 0.33541667 | K21: 0.83472222
A22: =A21 -> 1 | B22: 46239 | D22: =D21 -> Renaldi | E22: =SUMIFS(SSOD!$C:$C,SSOD!$B:$B,Hitungan!D22,SSOD!$A:$A,Hitungan!C22) -> 0 | G22: =E22*F22 -> 0 | H22: {=INDEX('Panduan Gaji'!$Q:$Q,MATCH(D22,'Panduan Gaji'!$C:$C,0))} -> Joglo | I22: 08 s.d 20 | J22: 0.32916667 | K22: 0.84166667
A23: =A22 -> 1 | B23: 46240 | D23: =D22 -> Renaldi | E23: =SUMIFS(SSOD!$C:$C,SSOD!$B:$B,Hitungan!D23,SSOD!$A:$A,Hitungan!C23) -> 0 | G23: =E23*F23 -> 0 | H23: {=INDEX('Panduan Gaji'!$Q:$Q,MATCH(D23,'Panduan Gaji'!$C:$C,0))} -> Joglo | I23: 08 s.d 20 | J23: 0.33472222 | K23: 0.83402778
A24: =A23 -> 1 | B24: 46241 | C24: Keterlambatan | D24: =D23 -> Renaldi | E24: =SUMIFS(SSOD!$C:$C,SSOD!$B:$B,Hitungan!D24,SSOD!$A:$A,Hitungan!C24) -> 19166.667 | F24: 1 | G24: =E24*F24 -> 19166.667 | H24: {=INDEX('Panduan Gaji'!$Q:$Q,MATCH(D24,'Panduan Gaji'!$C:$C,0))} -> Joglo | I24: 08 s.d 20 | J24: 0.3375 | K24: 0.83333333
A25: =A24 -> 1 | B25: 46242 | D25: =D24 -> Renaldi | E25: =SUMIFS(SSOD!$C:$C,SSOD!$B:$B,Hitungan!D25,SSOD!$A:$A,Hitungan!C25) -> 0 | G25: =E25*F25 -> 0 | H25: {=INDEX('Panduan Gaji'!$Q:$Q,MATCH(D25,'Panduan Gaji'!$C:$C,0))} -> Joglo | I25: 08 s.d 20 | J25: 0.33611111 | K25: 0.83472222
A26: =A25 -> 1 | B26: 46243 | D26: =D25 -> Renaldi | E26: =SUMIFS(SSOD!$C:$C,SSOD!$B:$B,Hitungan!D26,SSOD!$A:$A,Hitungan!C26) -> 0 | G26: =E26*F26 -> 0 | H26: {=INDEX('Panduan Gaji'!$Q:$Q,MATCH(D26,'Panduan Gaji'!$C:$C,0))} -> Joglo | I26: 08 s.d 20
A27: =A26 -> 1 | B27: 46244 | D27: =D26 -> Renaldi | E27: =SUMIFS(SSOD!$C:$C,SSOD!$B:$B,Hitungan!D27,SSOD!$A:$A,Hitungan!C27) -> 0 | G27: =E27*F27 -> 0 | H27: {=INDEX('Panduan Gaji'!$Q:$Q,MATCH(D27,'Panduan Gaji'!$C:$C,0))} -> Joglo | I27: 08 s.d 20 | J27: 0.33263889 | K27: 0.83333333
A28: =A27 -> 1 | B28: 46245 | D28: =D27 -> Renaldi | E28: =SUMIFS(SSOD!$C:$C,SSOD!$B:$B,Hitungan!D28,SSOD!$A:$A,Hitungan!C28) -> 0 | G28: =E28*F28 -> 0 | H28: {=INDEX('Panduan Gaji'!$Q:$Q,MATCH(D28,'Panduan Gaji'!$C:$C,0))} -> Joglo | I28: 08 s.d 20 | J28: 0.33055556 | K28: 0.83680556
A29: =A28 -> 1 | B29: 46246 | D29: =D28 -> Renaldi | E29: =SUMIFS(SSOD!$C:$C,SSOD!$B:$B,Hitungan!D29,SSOD!$A:$A,Hitungan!C29) -> 0 | G29: =E29*F29 -> 0 | H29: {=INDEX('Panduan Gaji'!$Q:$Q,MATCH(D29,'Panduan Gaji'!$C:$C,0))} -> Joglo | I29: 08 s.d 20 | J29: 0.33333333 | K29: 0.84513889
A30: =A29 -> 1 | B30: 46247 | D30: =D29 -> Renaldi | E30: =SUMIFS(SSOD!$C:$C,SSOD!$B:$B,Hitungan!D30,SSOD!$A:$A,Hitungan!C30) -> 0 | G30: =E30*F30 -> 0 | H30: {=INDEX('Panduan Gaji'!$Q:$Q,MATCH(D30,'Panduan Gaji'!$C:$C,0))} -> Joglo | I30: 08 s.d 20 | J30: 0.31944444 | K30: 0.84583333
A31: =A30 -> 1 | B31: 46248 | D31: =D30 -> Renaldi | E31: =SUMIFS(SSOD!$C:$C,SSOD!$B:$B,Hitungan!D31,SSOD!$A:$A,Hitungan!C31) -> 0 | G31: =E31*F31 -> 0 | H31: {=INDEX('Panduan Gaji'!$Q:$Q,MATCH(D31,'Panduan Gaji'!$C:$C,0))} -> Joglo | I31: 08 s.d 20 | J31: 0.33402778 | K31: 0.86944444
A32: =A31 -> 1 | B32: 46249 | D32: =D31 -> Renaldi | E32: =SUMIFS(SSOD!$C:$C,SSOD!$B:$B,Hitungan!D32,SSOD!$A:$A,Hitungan!C32) -> 0 | G32: =E32*F32 -> 0 | H32: {=INDEX('Panduan Gaji'!$Q:$Q,MATCH(D32,'Panduan Gaji'!$C:$C,0))} -> Joglo | I32: 08 s.d 20 | J32: 0.30763889 | K32: 0.83611111
A33: =A32 -> 1 | B33: 46250 | D33: =D32 -> Renaldi | E33: =SUMIFS(SSOD!$C:$C,SSOD!$B:$B,Hitungan!D33,SSOD!$A:$A,Hitungan!C33) -> 0 | G33: =E33*F33 -> 0 | H33: {=INDEX('Panduan Gaji'!$Q:$Q,MATCH(D33,'Panduan Gaji'!$C:$C,0))} -> Joglo | I33: 08 s.d 20
A34: =A33 -> 1 | B34: 46251 | D34: =D33 -> Renaldi | E34: =SUMIFS(SSOD!$C:$C,SSOD!$B:$B,Hitungan!D34,SSOD!$A:$A,Hitungan!C34) -> 0 | G34: =E34*F34 -> 0 | H34: {=INDEX('Panduan Gaji'!$Q:$Q,MATCH(D34,'Panduan Gaji'!$C:$C,0))} -> Joglo | I34: 08 s.d 20
A35: =A34 -> 1 | B35: 46252 | D35: =D34 -> Renaldi | E35: =SUMIFS(SSOD!$C:$C,SSOD!$B:$B,Hitungan!D35,SSOD!$A:$A,Hitungan!C35) -> 0 | G35: =E35*F35 -> 0 | H35: {=INDEX('Panduan Gaji'!$Q:$Q,MATCH(D35,'Panduan Gaji'!$C:$C,0))} -> Joglo | I35: 08 s.d 20 | J35: 0.325 | K35: 0.83958333
A36: =A35 -> 1 | B36: 46253 | D36: =D35 -> Renaldi | E36: =SUMIFS(SSOD!$C:$C,SSOD!$B:$B,Hitungan!D36,SSOD!$A:$A,Hitungan!C36) -> 0 | G36: =E36*F36 -> 0 | H36: {=INDEX('Panduan Gaji'!$Q:$Q,MATCH(D36,'Panduan Gaji'!$C:$C,0))} -> Joglo | I36: 08 s.d 20 | J36: 0.33541667 | K36: 0.84513889
A37: =A36 -> 1 | B37: 46254 | C37: Keterlambatan | D37: =D36 -> Renaldi | E37: =SUMIFS(SSOD!$C:$C,SSOD!$B:$B,Hitungan!D37,SSOD!$A:$A,Hitungan!C37) -> 19166.667 | F37: 1 | G37: =E37*F37 -> 19166.667 | H37: {=INDEX('Panduan Gaji'!$Q:$Q,MATCH(D37,'Panduan Gaji'!$C:$C,0))} -> Joglo | I37: 08 s.d 20 | J37: 0.34027778 | K37: 0.84652778
A38: =A37 -> 1 | B38: 46255 | C38: Lembur | D38: =D37 -> Renaldi | E38: =SUMIFS(SSOD!$C:$C,SSOD!$B:$B,Hitungan!D38,SSOD!$A:$A,Hitungan!C38) -> 19166.667 | F38: 1 | G38: =E38*F38 -> 19166.667 | H38: {=INDEX('Panduan Gaji'!$Q:$Q,MATCH(D38,'Panduan Gaji'!$C:$C,0))} -> Joglo | I38: 08 s.d 20 | J38: 0.32361111 | K38: 0.87847222
A39: =A38 -> 1 | B39: 46256 | D39: =D38 -> Renaldi | E39: =SUMIFS(SSOD!$C:$C,SSOD!$B:$B,Hitungan!D39,SSOD!$A:$A,Hitungan!C39) -> 0 | G39: =E39*F39 -> 0 | H39: {=INDEX('Panduan Gaji'!$Q:$Q,MATCH(D39,'Panduan Gaji'!$C:$C,0))} -> Joglo | I39: 08 s.d 20 | J39: 0.32916667 | K39: 0.84375
A40: =A39 -> 1 | B40: 46257 | D40: =D39 -> Renaldi | E40: =SUMIFS(SSOD!$C:$C,SSOD!$B:$B,Hitungan!D40,SSOD!$A:$A,Hitungan!C40) -> 0 | G40: =E40*F40 -> 0 | H40: {=INDEX('Panduan Gaji'!$Q:$Q,MATCH(D40,'Panduan Gaji'!$C:$C,0))} -> Joglo | I40: 08 s.d 20
...

Sheet SSOD
A1: Jenis | B1: Nama | C1: Rate | D1: Tagging
A2: Gaji Pokok | B2: Renaldi | C2: {=INDEX('Panduan Gaji'!$G:$G,MATCH(SSOD!B2,'Panduan Gaji'!$C:$C,0))} -> 1260000 | D2: {=INDEX('Panduan Gaji'!$Q:$Q,MATCH(SSOD!B2,'Panduan Gaji'!$C:$C,0))} -> Joglo
A3: Gaji Harian | B3: =B2 -> Renaldi | C3: {=INDEX('Panduan Gaji'!$F:$F,MATCH(SSOD!B3,'Panduan Gaji'!$C:$C,0))} | D3: {=INDEX('Panduan Gaji'!$Q:$Q,MATCH(SSOD!B3,'Panduan Gaji'!$C:$C,0))} -> Joglo
A4: Uang Transport | B4: =B3 -> Renaldi | C4: {=INDEX('Panduan Gaji'!$H:$H,MATCH(SSOD!B4,'Panduan Gaji'!$C:$C,0))} -> 65000 | D4: {=INDEX('Panduan Gaji'!$Q:$Q,MATCH(SSOD!B4,'Panduan Gaji'!$C:$C,0))} -> Joglo
A5: Uang Makan | B5: =B4 -> Renaldi | C5: {=INDEX('Panduan Gaji'!$I:$I,MATCH(SSOD!B5,'Panduan Gaji'!$C:$C,0))} -> 57500 | D5: {=INDEX('Panduan Gaji'!$Q:$Q,MATCH(SSOD!B5,'Panduan Gaji'!$C:$C,0))} -> Joglo
A6: Lembur | B6: =B5 -> Renaldi | C6: {=INDEX('Panduan Gaji'!$L:$L,MATCH(SSOD!B6,'Panduan Gaji'!$C:$C,0))} -> 19166.667 | D6: {=INDEX('Panduan Gaji'!$Q:$Q,MATCH(SSOD!B6,'Panduan Gaji'!$C:$C,0))} -> Joglo
A7: Keterlambatan | B7: =B6 -> Renaldi | C7: {=INDEX('Panduan Gaji'!$K:$K,MATCH(SSOD!B7,'Panduan Gaji'!$C:$C,0))} -> 19166.667 | D7: {=INDEX('Panduan Gaji'!$Q:$Q,MATCH(SSOD!B7,'Panduan Gaji'!$C:$C,0))} -> Joglo
A9: Gaji Pokok | B9: Ano | C9: {=INDEX('Panduan Gaji'!$G:$G,MATCH(SSOD!B9,'Panduan Gaji'!$C:$C,0))} -> 1250000 | D9: {=INDEX('Panduan Gaji'!$Q:$Q,MATCH(SSOD!B9,'Panduan Gaji'!$C:$C,0))} -> Joglo
A10: Gaji Harian | B10: =B9 -> Ano | C10: {=INDEX('Panduan Gaji'!$F:$F,MATCH(SSOD!B10,'Panduan Gaji'!$C:$C,0))} | D10: {=INDEX('Panduan Gaji'!$Q:$Q,MATCH(SSOD!B10,'Panduan Gaji'!$C:$C,0))} -> Joglo
A11: Uang Transport | B11: =B10 -> Ano | C11: {=INDEX('Panduan Gaji'!$H:$H,MATCH(SSOD!B11,'Panduan Gaji'!$C:$C,0))} -> 45000 | D11: {=INDEX('Panduan Gaji'!$Q:$Q,MATCH(SSOD!B11,'Panduan Gaji'!$C:$C,0))} -> Joglo
A12: Uang Makan | B12: =B11 -> Ano | C12: {=INDEX('Panduan Gaji'!$I:$I,MATCH(SSOD!B12,'Panduan Gaji'!$C:$C,0))} -> 55000 | D12: {=INDEX('Panduan Gaji'!$Q:$Q,MATCH(SSOD!B12,'Panduan Gaji'!$C:$C,0))} -> Joglo
A13: Lembur | B13: =B12 -> Ano | C13: {=INDEX('Panduan Gaji'!$L:$L,MATCH(SSOD!B13,'Panduan Gaji'!$C:$C,0))} -> 18333.333 | D13: {=INDEX('Panduan Gaji'!$Q:$Q,MATCH(SSOD!B13,'Panduan Gaji'!$C:$C,0))} -> Joglo
A14: Keterlambatan | B14: =B13 -> Ano | C14: {=INDEX('Panduan Gaji'!$K:$K,MATCH(SSOD!B14,'Panduan Gaji'!$C:$C,0))} -> 18333.333 | D14: {=INDEX('Panduan Gaji'!$Q:$Q,MATCH(SSOD!B14,'Panduan Gaji'!$C:$C,0))} -> Joglo
A16: Gaji Pokok | B16: Raihan | C16: {=INDEX('Panduan Gaji'!$G:$G,MATCH(SSOD!B16,'Panduan Gaji'!$C:$C,0))} -> 1250000 | D16: {=INDEX('Panduan Gaji'!$Q:$Q,MATCH(SSOD!B16,'Panduan Gaji'!$C:$C,0))} -> Joglo
A17: Gaji Harian | B17: =B16 -> Raihan | C17: {=INDEX('Panduan Gaji'!$F:$F,MATCH(SSOD!B17,'Panduan Gaji'!$C:$C,0))} | D17: {=INDEX('Panduan Gaji'!$Q:$Q,MATCH(SSOD!B17,'Panduan Gaji'!$C:$C,0))} -> Joglo
